Workbook

Sheet Home
B1: Press the button below before pasting anything
E8: 1. To start with complete a "Key Item" Stock Count, specifically counting the items that you need to order today, do not tick boxes of any other items. 2. If you have any red variances, go and double check your count to see if you have missed anything | Q8: 3. Once you have completed the stock count, head into "Reports" > "Report Selection" > "Supply Chain". From there you can select 2 reports 4. The first "Items On Hand" will require you to select tomorrow as the start date, then you can download it as "Excel Data Only" before pasting all the data into the "STOCK ON HAND" tab. 5. For the "Items On Order" report you will need to select Monday last week as the start date and Sunday 2 weeks from now as the End date, then download as "Excel Data Only", copy all that data into the "STOCK ON ORDER" tab
F36: ^This will be updated with Spot Count when available^ | M36: Once you have followed steps 1-5 all the numbers for your stock counts should be filled in, follow them!

Sheet WEEKLY PREP GUIDES
B1: ITEM NAME | C1: MONDAY | E1: TUESDAY | G1: WEDNESDAY | I1: THURSDAY | K1: FRIDAY | M1: SATURDAY | O1: SUNDAY | R1: DAILY AVG
B2: TOSTADA | C2: {=INDEX('AC and RGM only'!$N$1:$T$150, MATCH(TRUE, ISNUMBER(SEARCH($B$2, 'AC and RGM only'!$L$1:$L$150)), 0), MATCH(TRUE, ISNUMBER(SEARCH(C$1, 'AC and RGM only'!$D$2:$J$2)), 0))} -> 57 | E2: {=INDEX('AC and RGM only'!$N$1:$T$150, MATCH(TRUE, ISNUMBER(SEARCH($B$2, 'AC and RGM only'!$L$1:$L$150)), 0), MATCH(TRUE, ISNUMBER(SEARCH(E$1, 'AC and RGM only'!$D$2:$J$2)), 0))} -> 81 | G2: {=INDEX('AC and RGM only'!$N$1:$T$150, MATCH(TRUE, ISNUMBER(SEARCH($B$2, 'AC and RGM only'!$L$1:$L$150)), 0), MATCH(TRUE, ISNUMBER(SEARCH(G$1, 'AC and RGM only'!$D$2:$J$2)), 0))} -> 78 | I2: {=INDEX('AC and RGM only'!$N$1:$T$150, MATCH(TRUE, ISNUMBER(SEARCH($B$2, 'AC and RGM only'!$L$1:$L$150)), 0), MATCH(TRUE, ISNUMBER(SEARCH(I$1, 'AC and RGM only'!$D$2:$J$2)), 0))} -> 99 | K2: {=INDEX('AC and RGM only'!$N$1:$T$150, MATCH(TRUE, ISNUMBER(SEARCH($B$2, 'AC and RGM only'!$L$1:$L$150)), 0), MATCH(TRUE, ISNUMBER(SEARCH(K$1, 'AC and RGM only'!$D$2:$J$2)), 0))} -> 175 | M2: {=INDEX('AC and RGM only'!$N$1:$T$150, MATCH(TRUE, ISNUMBER(SEARCH($B$2, 'AC and RGM only'!$L$1:$L$150)), 0), MATCH(TRUE, ISNUMBER(SEARCH(M$1, 'AC and RGM only'!$D$2:$J$2)), 0))} -> 147 | O2: {=INDEX('AC and RGM only'!$N$1:$T$150, MATCH(TRUE, ISNUMBER(SEARCH($B$2, 'AC and RGM only'!$L$1:$L$150)), 0), MATCH(TRUE, ISNUMBER(SEARCH(O$1, 'AC and RGM only'!$D$2:$J$2)), 0))} -> 138 | R2: =AVERAGE(C2:O2) -> 110.71429
B3: TACO | C3: {=INDEX('AC and RGM only'!$N$1:$T$150, MATCH(TRUE, ISNUMBER(SEARCH($B$3, 'AC and RGM only'!$L$1:$L$150)), 0), MATCH(TRUE, ISNUMBER(SEARCH(C$1, 'AC and RGM only'!$D$2:$J$2)), 0))} -> 121 | E3: {=INDEX('AC and RGM only'!$N$1:$T$150, MATCH(TRUE, ISNUMBER(SEARCH($B$3, 'AC and RGM only'!$L$1:$L$150)), 0), MATCH(TRUE, ISNUMBER(SEARCH(E$1, 'AC and RGM only'!$D$2:$J$2)), 0))} -> 141 | G3: {=INDEX('AC and RGM only'!$N$1:$T$150, MATCH(TRUE, ISNUMBER(SEARCH($B$3, 'AC and RGM only'!$L$1:$L$150)), 0), MATCH(TRUE, ISNUMBER(SEARCH(G$1, 'AC and RGM only'!$D$2:$J$2)), 0))} -> 164 | I3: {=INDEX('AC and RGM only'!$N$1:$T$150, MATCH(TRUE, ISNUMBER(SEARCH($B$3, 'AC and RGM only'!$L$1:$L$150)), 0), MATCH(TRUE, ISNUMBER(SEARCH(I$1, 'AC and RGM only'!$D$2:$J$2)), 0))} -> 203 | K3: {=INDEX('AC and RGM only'!$N$1:$T$150, MATCH(TRUE, ISNUMBER(SEARCH($B$3, 'AC and RGM only'!$L$1:$L$150)), 0), MATCH(TRUE, ISNUMBER(SEARCH(K$1, 'AC and RGM only'!$D$2:$J$2)), 0))} -> 277 | M3: {=INDEX('AC and RGM only'!$N$1:$T$150, MATCH(TRUE, ISNUMBER(SEARCH($B$3, 'AC and RGM only'!$L$1:$L$150)), 0), MATCH(TRUE, ISNUMBER(SEARCH(M$1, 'AC and RGM only'!$D$2:$J$2)), 0))} -> 259 | O3: {=INDEX('AC and RGM only'!$N$1:$T$150, MATCH(TRUE, ISNUMBER(SEARCH($B$3, 'AC and RGM only'!$L$1:$L$150)), 0), MATCH(TRUE, ISNUMBER(SEARCH(O$1, 'AC and RGM only'!$D$2:$J$2)), 0))} -> 229 | R3: =AVERAGE(C3:O3) -> 199.14286
B4: CINNAMON TWISTS | C4: {=INDEX('AC and RGM only'!$N$1:$T$150, MATCH(TRUE, ISNUMBER(SEARCH($B$4, 'AC and RGM only'!$L$1:$L$150)), 0), MATCH(TRUE, ISNUMBER(SEARCH(C$1, 'AC and RGM only'!$D$2:$J$2)), 0))} -> 0.01 | E4: {=INDEX('AC and RGM only'!$N$1:$T$150, MATCH(TRUE, ISNUMBER(SEARCH($B$4, 'AC and RGM only'!$L$1:$L$150)), 0), MATCH(TRUE, ISNUMBER(SEARCH(E$1, 'AC and RGM only'!$D$2:$J$2)), 0))} -> 0.02 | G4: {=INDEX('AC and RGM only'!$N$1:$T$150, MATCH(TRUE, ISNUMBER(SEARCH($B$4, 'AC and RGM only'!$L$1:$L$150)), 0), MATCH(TRUE, ISNUMBER(SEARCH(G$1, 'AC and RGM only'!$D$2:$J$2)), 0))} -> 0.01 | I4: {=INDEX('AC and RGM only'!$N$1:$T$150, MATCH(TRUE, ISNUMBER(SEARCH($B$4, 'AC and RGM only'!$L$1:$L$150)), 0), MATCH(TRUE, ISNUMBER(SEARCH(I$1, 'AC and RGM only'!$D$2:$J$2)), 0))} -> 0 | K4: {=INDEX('AC and RGM only'!$N$1:$T$150, MATCH(TRUE, ISNUMBER(SEARCH($B$4, 'AC and RGM only'!$L$1:$L$150)), 0), MATCH(TRUE, ISNUMBER(SEARCH(K$1, 'AC and RGM only'!$D$2:$J$2)), 0))} -> 0.01 | M4: {=INDEX('AC and RGM only'!$N$1:$T$150, MATCH(TRUE, ISNUMBER(SEARCH($B$4, 'AC and RGM only'!$L$1:$L$150)), 0), MATCH(TRUE, ISNUMBER(SEARCH(M$1, 'AC and RGM only'!$D$2:$J$2)), 0))} -> 0 | O4: {=INDEX('AC and RGM only'!$N$1:$T$150, MATCH(TRUE, ISNUMBER(SEARCH($B$4, 'AC and RGM only'!$L$1:$L$150)), 0), MATCH(TRUE, ISNUMBER(SEARCH(O$1, 'AC and RGM only'!$D$2:$J$2)), 0))} -> 0 | R4: =AVERAGE(C4:O4) -> 0.0071428571
B5: CHIP NACHO CORN | C5: {=INDEX('AC and RGM only'!$N$1:$T$150, MATCH(TRUE, ISNUMBER(SEARCH($B$5, 'AC and RGM only'!$L$1:$L$150)), 0), MATCH(TRUE, ISNUMBER(SEARCH(C$1, 'AC and RGM only'!$D$2:$J$2)), 0))} -> 0.34 | E5: {=INDEX('AC and RGM only'!$N$1:$T$150, MATCH(TRUE, ISNUMBER(SEARCH($B$5, 'AC and RGM only'!$L$1:$L$150)), 0), MATCH(TRUE, ISNUMBER(SEARCH(E$1, 'AC and RGM only'!$D$2:$J$2)), 0))} -> 0.48 | G5: {=INDEX('AC and RGM only'!$N$1:$T$150, MATCH(TRUE, ISNUMBER(SEARCH($B$5, 'AC and RGM only'!$L$1:$L$150)), 0), MATCH(TRUE, ISNUMBER(SEARCH(G$1, 'AC and RGM only'!$D$2:$J$2)), 0))} -> 0.37 | I5: {=INDEX('AC and RGM only'!$N$1:$T$150, MATCH(TRUE, ISNUMBER(SEARCH($B$5, 'AC and RGM only'!$L$1:$L$150)), 0), MATCH(TRUE, ISNUMBER(SEARCH(I$1, 'AC and RGM only'!$D$2:$J$2)), 0))} -> 0.51 | K5: {=INDEX('AC and RGM only'!$N$1:$T$150, MATCH(TRUE, ISNUMBER(SEARCH($B$5, 'AC and RGM only'!$L$1:$L$150)), 0), MATCH(TRUE, ISNUMBER(SEARCH(K$1, 'AC and RGM only'!$D$2:$J$2)), 0))} -> 0.93 | M5: {=INDEX('AC and RGM only'!$N$1:$T$150, MATCH(TRUE, ISNUMBER(SEARCH($B$5, 'AC and RGM only'!$L$1:$L$150)), 0), MATCH(TRUE, ISNUMBER(SEARCH(M$1, 'AC and RGM only'!$D$2:$J$2)), 0))} -> 0.99 | O5: {=INDEX('AC and RGM only'!$N$1:$T$150, MATCH(TRUE, ISNUMBER(SEARCH($B$5, 'AC and RGM only'!$L$1:$L$150)), 0), MATCH(TRUE, ISNUMBER(SEARCH(O$1, 'AC and RGM only'!$D$2:$J$2)), 0))} -> 1 | R5: =AVERAGE(C5:O5) -> 0.66
B7: ITEM NAME | C7: # OF BAGS | D7: # OF TRAYS | E7: # OF BAGS | F7: # OF TRAYS | G7: # OF BAGS | H7: # OF TRAYS | I7: # OF BAGS | J7: # OF TRAYS | K7: # OF BAGS | L7: # OF TRAYS | M7: # OF BAGS | N7: # OF TRAYS | O7: # OF BAGS | P7: # OF TRAYS | R7: QUICK GUIDE
B8: TOSTADAS | C8: =SUM(C2:E2)/36 -> 3.8333333 | D8: =ROUNDUP(C8/$T$10,0) -> 2 | E8: =SUM(E2:G2)/36 -> 4.4166667 | F8: =ROUNDUP(E8/$T$10,0) -> 2 | G8: =SUM(G2:I2)/36 -> 4.9166667 | H8: =ROUNDUP(G8/$T$10,0) -> 2 | I8: =SUM(I2:K2)/36 -> 7.6111111 | J8: =ROUNDUP(I8/$T$10,0) -> 3 | K8: =SUM(K2+M2)/36 -> 8.9444444 | L8: =ROUNDUP(K8/$T$10,0) -> 3 | M8: =SUM(M2+O2)/36 -> 7.9166667 | N8: =ROUNDUP(M8/$T$10,0) -> 3 | O8: =SUM(O2+C2)/36 -> 5.4166667 | P8: =ROUNDUP(O8/$T$10,0) -> 2 | R8: CINNAMON TWISTS | S8: 2 REDS CUP = 1 TRAY
B9: TACOS | C9: =SUM(C3:E3)/36 -> 7.2777778 | D9: =ROUNDUP(C9/$T$11,0) -> 3 | E9: =SUM(E3:G3)/36 -> 8.4722222 | F9: =ROUNDUP(E9/$T$11,0) -> 3 | G9: =SUM(G3:I3)/36 -> 10.194444 | H9: =ROUNDUP(G9/$T$11,0) -> 4 | I9: =SUM(I3:K3)/36 -> 13.333333 | J9: =ROUNDUP(I9/$T$11,0) -> 5 | K9: =SUM(K3+M3)/36 -> 14.888889 | L9: =ROUNDUP(K9/$T$11,0) -> 5 | M9: =SUM(M3+O3)/36 -> 13.555556 | N9: =ROUNDUP(M9/$T$11,0) -> 5 | O9: =SUM(O3+C3)/36 -> 9.7222222 | P9: =ROUNDUP(O9/$T$11,0) -> 4 | R9: NACHO CHIPS | S9: 1 BOX = 1.5 LARGE TUBS
B10: CINNAMON TWISTS | C10: {=_xlfn.LET( _xlpm.GRAMSOFTWIST,C4, _xlpm.GRAMSPERCUP,10, _xlpm.GRAMSOFTWIST*_xlpm.GRAMSPERCUP)} -> 0.1 | D10: =C10/0.15 -> 0.66666667 | E10: {=_xlfn.LET( _xlpm.GRAMSOFTWIST,E4, _xlpm.GRAMSPERCUP,10, _xlpm.GRAMSOFTWIST*_xlpm.GRAMSPERCUP)} -> 0.2 | F10: =E10/0.15 -> 1.3333333 | G10: {=_xlfn.LET( _xlpm.GRAMSOFTWIST,G4, _xlpm.GRAMSPERCUP,10, _xlpm.GRAMSOFTWIST*_xlpm.GRAMSPERCUP)} -> 0.1 | H10: =G10/0.15 -> 0.66666667 | I10: {=_xlfn.LET( _xlpm.GRAMSOFTWIST,I4, _xlpm.GRAMSPERCUP,10, _xlpm.GRAMSOFTWIST*_xlpm.GRAMSPERCUP)} -> 0 | J10: =I10/0.15 -> 0 | K10: {=_xlfn.LET( _xlpm.GRAMSOFTWIST,K4, _xlpm.GRAMSPERCUP,10, _xlpm.GRAMSOFTWIST*_xlpm.GRAMSPERCUP)} -> 0.1 | L10: =K10/0.15 -> 0.66666667 | M10: {=_xlfn.LET( _xlpm.GRAMSOFTWIST,M4, _xlpm.GRAMSPERCUP,10, _xlpm.GRAMSOFTWIST*_xlpm.GRAMSPERCUP)} -> 0 | N10: =M10/0.15 -> 0 | O10: {=_xlfn.LET( _xlpm.GRAMSOFTWIST,O4, _xlpm.GRAMSPERCUP,10, _xlpm.GRAMSOFTWIST*_xlpm.GRAMSPERCUP)} -> 0 | P10: =O10/0.15 -> 0 | R10: TOSTADAS | S10: Bags Per Tray | T10: 3
B11: NACHOS | C11: =SUM(C5:E5) -> 0.82 | E11: =SUM(E5:G5) -> 0.85 | G11: =SUM(G5:I5) -> 0.88 | I11: =SUM(I5:K5) -> 1.44 | K11: =SUM(K5+M5) -> 1.92 | M11: =SUM(M5+O5) -> 1.99 | O11: =SUM(O5+C5) -> 1.34 | R11: TACOS | S11: Bags Per Tray | T11: 3
E14: WEEKLY FRY PREP BUILD TOS | O14: Data Range:
O15: =TRIM(RIGHT(SUBSTITUTE('AC and RGM only'!D2,CHAR(10),REPT(" ",100)),100)) & " to " & TRIM(RIGHT(SUBSTITUTE('AC and RGM only'!J2,CHAR(10),REPT(" ",100)),100)) -> 14-May-26 to 20-May-26
C17: MONDAY | H17: TUESDAY | M17: WEDNESDAY
C18: ITEM | E18: AMOUNT | H18: ITEM | J18: AMOUNT | M18: ITEM | O18: AMOUNT
C19: TOSTADAS | E19: =D8 & " TRAYS" -> 2 TRAYS | H19: TOSTADAS | J19: =F8 & " TRAYS" -> 2 TRAYS | M19: TOSTADAS | O19: =H8 & " TRAYS" -> 2 TRAYS
C20: TACOS | E20: =D9 & " TRAYS" -> 3 TRAYS | H20: TACOS | J20: =F9 & " TRAYS" -> 3 TRAYS | M20: TACOS | O20: =H9 & " TRAYS" -> 4 TRAYS
C21: CINNAMON TWISTS | E21: =ROUNDUP(D10,0) & " RED CUPS" -> 1 RED CUPS | H21: CINNAMON TWISTS | J21: =ROUNDUP(F10,0) & " RED CUPS" -> 2 RED CUPS | M21: CINNAMON TWISTS | O21: =ROUNDUP(H10,0) & " RED CUPS" -> 1 RED CUPS
C22: NACHOS | E22: =_xlfn.LET(_xlpm.NumberOfBoxes,C11, _xlpm.NumberOfTubsPerBox,1.5, _xlpm.RoundTo,0.5, MROUND(_xlpm.NumberOfBoxes*_xlpm.NumberOfTubsPerBox,_xlpm.RoundTo)&" TUBS") -> 1 TUBS | H22: NACHOS | J22: =_xlfn.LET(_xlpm.NumberOfBoxes,E11, _xlpm.NumberOfTubsPerBox,1.5, _xlpm.RoundTo,0.5, MROUND(_xlpm.NumberOfBoxes*_xlpm.NumberOfTubsPerBox,_xlpm.RoundTo)&" TUBS") -> 1.5 TUBS | M22: NACHOS | O22: =_xlfn.LET(_xlpm.NumberOfBoxes,G11, _xlpm.NumberOfTubsPerBox,1.5, _xlpm.RoundTo,0.5, MROUND(_xlpm.NumberOfBoxes*_xlpm.NumberOfTubsPerBox,_xlpm.RoundTo)&" TUBS") -> 1.5 TUBS
C24: THURSDAY | H24: FRIDAY | M24: SATURDAY
C25: ITEM | E25: AMOUNT | H25: ITEM | J25: AMOUNT | M25: ITEM | O25: AMOUNT
C26: TOSTADAS | E26: =J8 & " TRAYS" -> 3 TRAYS | H26: TOSTADAS | J26: =L8 & " TRAYS" -> 3 TRAYS | M26: TOSTADAS | O26: =N8 & " TRAYS" -> 3 TRAYS
C27: TACOS | E27: =J9 & " TRAYS" -> 5 TRAYS | H27: TACOS | J27: =L9 & " TRAYS" -> 5 TRAYS | M27: TACOS | O27: =N9 & " TRAYS" -> 5 TRAYS
C28: CINNAMON TWISTS | E28: =ROUNDUP(J10,0) & " RED CUPS" -> 0 RED CUPS | H28: CINNAMON TWISTS | J28: =ROUNDUP(L10,0) & " RED CUPS" -> 1 RED CUPS | M28: CINNAMON TWISTS | O28: =ROUNDUP(N10,0) & " RED CUPS" -> 0 RED CUPS
C29: NACHOS | E29: =_xlfn.LET(_xlpm.NumberOfBoxes,I11, _xlpm.NumberOfTubsPerBox,1.5, _xlpm.RoundTo,0.5, MROUND(_xlpm.NumberOfBoxes*_xlpm.NumberOfTubsPerBox,_xlpm.RoundTo)&" TUBS") -> 2 TUBS | H29: NACHOS | J29: =_xlfn.LET(_xlpm.NumberOfBoxes,K11, _xlpm.NumberOfTubsPerBox,1.5, _xlpm.RoundTo,0.5, MROUND(_xlpm.NumberOfBoxes*_xlpm.NumberOfTubsPerBox,_xlpm.RoundTo)&" TUBS") -> 3 TUBS | M29: NACHOS | O29: =_xlfn.LET(_xlpm.NumberOfBoxes,M11, _xlpm.NumberOfTubsPerBox,1.5, _xlpm.RoundTo,0.5, MROUND(_xlpm.NumberOfBoxes*_xlpm.NumberOfTubsPerBox,_xlpm.RoundTo)&" TUBS") -> 3 TUBS
H31: SUNDAY
H32: ITEM | J32: AMOUNT
H33: TOSTADAS | J33: =P8 & " TRAYS" -> 2 TRAYS
H34: TACOS | J34: =P9 & " TRAYS" -> 4 TRAYS
H35: CINNAMON TWISTS | J35: =ROUNDUP(P10,0) & " RED CUPS" -> 0 RED CUPS
H36: NACHOS | J36: =_xlfn.LET(_xlpm.NumberOfBoxes,O11, _xlpm.NumberOfTubsPerBox,1.5, _xlpm.RoundTo,0.5, MROUND(_xlpm.NumberOfBoxes*_xlpm.NumberOfTubsPerBox,_xlpm.RoundTo)&" TUBS") -> 2 TUBS
C38: VALUES FOR TRAYS ROUNDED UP BASED OFF MAKING 5 ROWS OF 16 TACOS (2 BASKETS PER ROW, 80 TACOS PER TRAY)
B40: ITEM NAME | C40: MONDAY | E40: TUESDAY | G40: WEDNESDAY | I40: THURSDAY | K40: FRIDAY | M40: SATURDAY | O40: SUNDAY | R40: DAILY AVG
B41: CREAM SOUR | C41: {=INDEX('AC and RGM only'!$N$1:$T$150, MATCH(TRUE, ISNUMBER(SEARCH($B$41, 'AC and RGM only'!$L$1:$L$150)), 0), MATCH(TRUE, ISNUMBER(SEARCH(C$40, 'AC and RGM only'!$D$2:$J$2)), 0))} -> 0.48 | E41: {=INDEX('AC and RGM only'!$N$1:$T$150, MATCH(TRUE, ISNUMBER(SEARCH($B$41, 'AC and RGM only'!$L$1:$L$150)), 0), MATCH(TRUE, ISNUMBER(SEARCH(E$40, 'AC and RGM only'!$D$2:$J$2)), 0))} -> 0.72 | G41: {=INDEX('AC and RGM only'!$N$1:$T$150, MATCH(TRUE, ISNUMBER(SEARCH($B$41, 'AC and RGM only'!$L$1:$L$150)), 0), MATCH(TRUE, ISNUMBER(SEARCH(G$40, 'AC and RGM only'!$D$2:$J$2)), 0))} -> 0.62 | I41: {=INDEX('AC and RGM only'!$N$1:$T$150, MATCH(TRUE, ISNUMBER(SEARCH($B$41, 'AC and RGM only'!$L$1:$L$150)), 0), MATCH(TRUE, ISNUMBER(SEARCH(I$40, 'AC and RGM only'!$D$2:$J$2)), 0))} -> 0.91 | K41: {=INDEX('AC and RGM only'!$N$1:$T$150, MATCH(TRUE, ISNUMBER(SEARCH($B$41, 'AC and RGM only'!$L$1:$L$150)), 0), MATCH(TRUE, ISNUMBER(SEARCH(K$40, 'AC and RGM only'!$D$2:$J$2)), 0))} -> 1.42 | M41: {=INDEX('AC and RGM only'!$N$1:$T$150, MATCH(TRUE, ISNUMBER(SEARCH($B$41, 'AC and RGM only'!$L$1:$L$150)), 0), MATCH(TRUE, ISNUMBER(SEARCH(M$40, 'AC and RGM only'!$D$2:$J$2)), 0))} -> 1.18 | O41: {=INDEX('AC and RGM only'!$N$1:$T$150, MATCH(TRUE, ISNUMBER(SEARCH($B$41, 'AC and RGM only'!$L$1:$L$150)), 0), MATCH(TRUE, ISNUMBER(SEARCH(O$40, 'AC and RGM only'!$D$2:$J$2)), 0))} -> 1.19 | R41: =AVERAGE(C41:O41) -> 0.93142857
B42: ZESTY | C42: {=INDEX('AC and RGM only'!$N$1:$T$150, MATCH(TRUE, ISNUMBER(SEARCH($B$42, 'AC and RGM only'!$L$1:$L$150)), 0), MATCH(TRUE, ISNUMBER(SEARCH(C$40, 'AC and RGM only'!$D$2:$J$2)), 0))} -> 0.18 | E42: {=INDEX('AC and RGM only'!$N$1:$T$150, MATCH(TRUE, ISNUMBER(SEARCH($B$42, 'AC and RGM only'!$L$1:$L$150)), 0), MATCH(TRUE, ISNUMBER(SEARCH(E$40, 'AC and RGM only'!$D$2:$J$2)), 0))} -> 0.23 | G42: {=INDEX('AC and RGM only'!$N$1:$T$150, MATCH(TRUE, ISNUMBER(SEARCH($B$42, 'AC and RGM only'!$L$1:$L$150)), 0), MATCH(TRUE, ISNUMBER(SEARCH(G$40, 'AC and RGM only'!$D$2:$J$2)), 0))} -> 0.21 | I42: {=INDEX('AC and RGM only'!$N$1:$T$150, MATCH(TRUE, ISNUMBER(SEARCH($B$42, 'AC and RGM only'!$L$1:$L$150)), 0), MATCH(TRUE, ISNUMBER(SEARCH(I$40, 'AC and RGM only'!$D$2:$J$2)), 0))} -> 0.27 | K42: {=INDEX('AC and RGM only'!$N$1:$T$150, MATCH(TRUE, ISNUMBER(SEARCH($B$42, 'AC and RGM only'!$L$1:$L$150)), 0), MATCH(TRUE, ISNUMBER(SEARCH(K$40, 'AC and RGM only'!$D$2:$J$2)), 0))} -> 0.41 | M42: {=INDEX('AC and RGM only'!$N$1:$T$150, MATCH(TRUE, ISNUMBER(SEARCH($B$42, 'AC and RGM only'!$L$1:$L$150)), 0), MATCH(TRUE, ISNUMBER(SEARCH(M$40, 'AC and RGM only'!$D$2:$J$2)), 0))} -> 0.33 | O42: {=INDEX('AC and RGM only'!$N$1:$T$150, MATCH(TRUE, ISNUMBER(SEARCH($B$42, 'AC and RGM only'!$L$1:$L$150)), 0), MATCH(TRUE, ISNUMBER(SEARCH(O$40, 'AC and RGM only'!$D$2:$J$2)), 0))} -> 0.39 | R42: =AVERAGE(C42:O42) -> 0.28857143
B43: CHIPOTLE | C43: {=INDEX('AC and RGM only'!$N$1:$T$150, MATCH(TRUE, ISNUMBER(SEARCH($B$43, 'AC and RGM only'!$L$1:$L$150)), 0), MATCH(TRUE, ISNUMBER(SEARCH(C$40, 'AC and RGM only'!$D$2:$J$2)), 0))} -> 0.11 | E43: {=INDEX('AC and RGM only'!$N$1:$T$150, MATCH(TRUE, ISNUMBER(SEARCH($B$43, 'AC and RGM only'!$L$1:$L$150)), 0), MATCH(TRUE, ISNUMBER(SEARCH(E$40, 'AC and RGM only'!$D$2:$J$2)), 0))} -> 0.11 | G43: {=INDEX('AC and RGM only'!$N$1:$T$150, MATCH(TRUE, ISNUMBER(SEARCH($B$43, 'AC and RGM only'!$L$1:$L$150)), 0), MATCH(TRUE, ISNUMBER(SEARCH(G$40, 'AC and RGM only'!$D$2:$J$2)), 0))} -> 0.11 | I43: {=INDEX('AC and RGM only'!$N$1:$T$150, MATCH(TRUE, ISNUMBER(SEARCH($B$43, 'AC and RGM only'!$L$1:$L$150)), 0), MATCH(TRUE, ISNUMBER(SEARCH(I$40, 'AC and RGM only'!$D$2:$J$2)), 0))} -> 0.15 | K43: {=INDEX('AC and RGM only'!$N$1:$T$150, MATCH(TRUE, ISNUMBER(SEARCH($B$43, 'AC and RGM only'!$L$1:$L$150)), 0), MATCH(TRUE, ISNUMBER(SEARCH(K$40, 'AC and RGM only'!$D$2:$J$2)), 0))} -> 0.22 | M43: {=INDEX('AC and RGM only'!$N$1:$T$150, MATCH(TRUE, ISNUMBER(SEARCH($B$43, 'AC and RGM only'!$L$1:$L$150)), 0), MATCH(TRUE, ISNUMBER(SEARCH(M$40, 'AC and RGM only'!$D$2:$J$2)), 0))} -> 0.21 | O43: {=INDEX('AC and RGM only'!$N$1:$T$150, MATCH(TRUE, ISNUMBER(SEARCH($B$43, 'AC and RGM only'!$L$1:$L$150)), 0), MATCH(TRUE, ISNUMBER(SEARCH(O$40, 'AC and RGM only'!$D$2:$J$2)), 0))} -> 0.18 | R43: =AVERAGE(C43:O43) -> 0.15571429
B44: LAVA | C44: {=INDEX('AC and RGM only'!$N$1:$T$150, MATCH(TRUE, ISNUMBER(SEARCH($B$44, 'AC and RGM only'!$L$1:$L$150)), 0), MATCH(TRUE, ISNUMBER(SEARCH(C$40, 'AC and RGM only'!$D$2:$J$2)), 0))} -> 0.07 | E44: {=INDEX('AC and RGM only'!$N$1:$T$150, MATCH(TRUE, ISNUMBER(SEARCH($B$44, 'AC and RGM only'!$L$1:$L$150)), 0), MATCH(TRUE, ISNUMBER(SEARCH(E$40, 'AC and RGM only'!$D$2:$J$2)), 0))} -> 0.06 | G44: {=INDEX('AC and RGM only'!$N$1:$T$150, MATCH(TRUE, ISNUMBER(SEARCH($B$44, 'AC and RGM only'!$L$1:$L$150)), 0), MATCH(TRUE, ISNUMBER(SEARCH(G$40, 'AC and RGM only'!$D$2:$J$2)), 0))} -> 0.06 | I44: {=INDEX('AC and RGM only'!$N$1:$T$150, MATCH(TRUE, ISNUMBER(SEARCH($B$44, 'AC and RGM only'!$L$1:$L$150)), 0), MATCH(TRUE, ISNUMBER(SEARCH(I$40, 'AC and RGM only'!$D$2:$J$2)), 0))} -> 0.04 | K44: {=INDEX('AC and RGM only'!$N$1:$T$150, MATCH(TRUE, ISNUMBER(SEARCH($B$44, 'AC and RGM only'!$L$1:$L$150)), 0), MATCH(TRUE, ISNUMBER(SEARCH(K$40, 'AC and RGM only'!$D$2:$J$2)), 0))} -> 0.12 | M44: {=INDEX('AC and RGM only'!$N$1:$T$150, MATCH(TRUE, ISNUMBER(SEARCH($B$44, 'AC and RGM only'!$L$1:$L$150)), 0), MATCH(TRUE, ISNUMBER(SEARCH(M$40, 'AC and RGM only'!$D$2:$J$2)), 0))} -> 0.07 | O44: {=INDEX('AC and RGM only'!$N$1:$T$150, MATCH(TRUE, ISNUMBER(SEARCH($B$44, 'AC and RGM only'!$L$1:$L$150)), 0), MATCH(TRUE, ISNUMBER(SEARCH(O$40, 'AC and RGM only'!$D$2:$J$2)), 0))} -> 0.11 | R44: =AVERAGE(C44:O44) -> 0.075714286
B45: CREAMY J | C45: {=INDEX('AC and RGM only'!$N$1:$T$150, MATCH(TRUE, ISNUMBER(SEARCH($B$45, 'AC and RGM only'!$L$1:$L$150)), 0), MATCH(TRUE, ISNUMBER(SEARCH(C$40, 'AC and RGM only'!$D$2:$J$2)), 0))} -> 0.07 | E45: {=INDEX('AC and RGM only'!$N$1:$T$150, MATCH(TRUE, ISNUMBER(SEARCH($B$45, 'AC and RGM only'!$L$1:$L$150)), 0), MATCH(TRUE, ISNUMBER(SEARCH(E$40, 'AC and RGM only'!$D$2:$J$2)), 0))} -> 0.06 | G45: {=INDEX('AC and RGM only'!$N$1:$T$150, MATCH(TRUE, ISNUMBER(SEARCH($B$45, 'AC and RGM only'!$L$1:$L$150)), 0), MATCH(TRUE, ISNUMBER(SEARCH(G$40, 'AC and RGM only'!$D$2:$J$2)), 0))} -> 0.06 | I45: {=INDEX('AC and RGM only'!$N$1:$T$150, MATCH(TRUE, ISNUMBER(SEARCH($B$45, 'AC and RGM only'!$L$1:$L$150)), 0), MATCH(TRUE, ISNUMBER(SEARCH(I$40, 'AC and RGM only'!$D$2:$J$2)), 0))} -> 0.07 | K45: {=INDEX('AC and RGM only'!$N$1:$T$150, MATCH(TRUE, ISNUMBER(SEARCH($B$45, 'AC and RGM only'!$L$1:$L$150)), 0), MATCH(TRUE, ISNUMBER(SEARCH(K$40, 'AC and RGM only'!$D$2:$J$2)), 0))} -> 0.12 | M45: {=INDEX('AC and RGM only'!$N$1:$T$150, MATCH(TRUE, ISNUMBER(SEARCH($B$45, 'AC and RGM only'!$L$1:$L$150)), 0), MATCH(TRUE, ISNUMBER(SEARCH(M$40, 'AC and RGM only'!$D$2:$J$2)), 0))} -> 0.07 | O45: {=INDEX('AC and RGM only'!$N$1:$T$150, MATCH(TRUE, ISNUMBER(SEARCH($B$45, 'AC and RGM only'!$L$1:$L$150)), 0), MATCH(TRUE, ISNUMBER(SEARCH(O$40, 'AC and RGM only'!$D$2:$J$2)), 0))} -> 0.1 | R45: =AVERAGE(C45:O45) -> 0.078571429
B46: MILD | C46: {=INDEX('AC and RGM only'!$N$1:$T$150, MATCH(TRUE, ISNUMBER(SEARCH($B$46, 'AC and RGM only'!$L$1:$L$150)), 0), MATCH(TRUE, ISNUMBER(SEARCH(C$40, 'AC and RGM only'!$D$2:$J$2)), 0))} -> 0.1 | E46: {=INDEX('AC and RGM only'!$N$1:$T$150, MATCH(TRUE, ISNUMBER(SEARCH($B$46, 'AC and RGM only'!$L$1:$L$150)), 0), MATCH(TRUE, ISNUMBER(SEARCH(E$40, 'AC and RGM only'!$D$2:$J$2)), 0))} -> 0.14 | G46: {=INDEX('AC and RGM only'!$N$1:$T$150, MATCH(TRUE, ISNUMBER(SEARCH($B$46, 'AC and RGM only'!$L$1:$L$150)), 0), MATCH(TRUE, ISNUMBER(SEARCH(G$40, 'AC and RGM only'!$D$2:$J$2)), 0))} -> 0.16 | I46: {=INDEX('AC and RGM only'!$N$1:$T$150, MATCH(TRUE, ISNUMBER(SEARCH($B$46, 'AC and RGM only'!$L$1:$L$150)), 0), MATCH(TRUE, ISNUMBER(SEARCH(I$40, 'AC and RGM only'!$D$2:$J$2)), 0))} -> 0.22 | K46: {=INDEX('AC and RGM only'!$N$1:$T$150, MATCH(TRUE, ISNUMBER(SEARCH($B$46, 'AC and RGM only'!$L$1:$L$150)), 0), MATCH(TRUE, ISNUMBER(SEARCH(K$40, 'AC and RGM only'!$D$2:$J$2)), 0))} -> 0.27 | M46: {=INDEX('AC and RGM only'!$N$1:$T$150, MATCH(TRUE, ISNUMBER(SEARCH($B$46, 'AC and RGM only'!$L$1:$L$150)), 0), MATCH(TRUE, ISNUMBER(SEARCH(M$40, 'AC and RGM only'!$D$2:$J$2)), 0))} -> 0.24 | O46: {=INDEX('AC and RGM only'!$N$1:$T$150, MATCH(TRUE, ISNUMBER(SEARCH($B$46, 'AC and RGM only'!$L$1:$L$150)), 0), MATCH(TRUE, ISNUMBER(SEARCH(O$40, 'AC and RGM only'!$D$2:$J$2)), 0))} -> 0.22 | R46: =AVERAGE(C46:O46) -> 0.19285714
B47: FIRE | C47: {=INDEX('AC and RGM only'!$N3:$T152, MATCH(TRUE, ISNUMBER(SEARCH($B$47, 'AC and RGM only'!$L3:$L152)), 0), MATCH(TRUE, ISNUMBER(SEARCH(C$40, 'AC and RGM only'!$D$2:$J$2)), 0))} -> 0.03 | E47: {=INDEX('AC and RGM only'!$N3:$T152, MATCH(TRUE, ISNUMBER(SEARCH($B$47, 'AC and RGM only'!$L3:$L152)), 0), MATCH(TRUE, ISNUMBER(SEARCH(E$40, 'AC and RGM only'!$D$2:$J$2)), 0))} -> 0.04 | G47: {=INDEX('AC and RGM only'!$N3:$T152, MATCH(TRUE, ISNUMBER(SEARCH($B$47, 'AC and RGM only'!$L3:$L152)), 0), MATCH(TRUE, ISNUMBER(SEARCH(G$40, 'AC and RGM only'!$D$2:$J$2)), 0))} -> 0.05 | I47: {=INDEX('AC and RGM only'!$N3:$T152, MATCH(TRUE, ISNUMBER(SEARCH($B$47, 'AC and RGM only'!$L3:$L152)), 0), MATCH(TRUE, ISNUMBER(SEARCH(I$40, 'AC and RGM only'!$D$2:$J$2)), 0))} -> 0.08 | K47: {=INDEX('AC and RGM only'!$N3:$T152, MATCH(TRUE, ISNUMBER(SEARCH($B$47, 'AC and RGM only'!$L3:$L152)), 0), MATCH(TRUE, ISNUMBER(SEARCH(K$40, 'AC and RGM only'!$D$2:$J$2)), 0))} -> 0.1 | M47: {=INDEX('AC and RGM only'!$N3:$T152, MATCH(TRUE, ISNUMBER(SEARCH($B$47, 'AC and RGM only'!$L3:$L152)), 0), MATCH(TRUE, ISNUMBER(SEARCH(M$40, 'AC and RGM only'!$D$2:$J$2)), 0))} -> 0.07 | O47: {=INDEX('AC and RGM only'!$N3:$T152, MATCH(TRUE, ISNUMBER(SEARCH($B$47, 'AC and RGM only'!$L3:$L152)), 0), MATCH(TRUE, ISNUMBER(SEARCH(O$40, 'AC and RGM only'!$D$2:$J$2)), 0))} -> 0.06 | R47: =AVERAGE(C47:O47) -> 0.061428571
B48: TB FIESTA SALSA (FINISHED PRODUCT) | C48: {=INDEX('AC and RGM only'!$N4:$T153, MATCH(TRUE, ISNUMBER(SEARCH($B$48, 'AC and RGM only'!$L4:$L153)), 0), MATCH(TRUE, ISNUMBER(SEARCH(C$40, 'AC and RGM only'!$D$2:$J$2)), 0))} -> 0.94 | E48: {=INDEX('AC and RGM only'!$N4:$T153, MATCH(TRUE, ISNUMBER(SEARCH($B$48, 'AC and RGM only'!$L4:$L153)), 0), MATCH(TRUE, ISNUMBER(SEARCH(E$40, 'AC and RGM only'!$D$2:$J$2)), 0))} -> 1.36 | G48: {=INDEX('AC and RGM only'!$N4:$T153, MATCH(TRUE, ISNUMBER(SEARCH($B$48, 'AC and RGM only'!$L4:$L153)), 0), MATCH(TRUE, ISNUMBER(SEARCH(G$40, 'AC and RGM only'!$D$2:$J$2)), 0))} -> 1.02 | I48: {=INDEX('AC and RGM only'!$N4:$T153, MATCH(TRUE, ISNUMBER(SEARCH($B$48, 'AC and RGM only'!$L4:$L153)), 0), MATCH(TRUE, ISNUMBER(SEARCH(I$40, 'AC and RGM only'!$D$2:$J$2)), 0))} -> 1.62 | K48: {=INDEX('AC and RGM only'!$N4:$T153, MATCH(TRUE, ISNUMBER(SEARCH($B$48, 'AC and RGM only'!$L4:$L153)), 0), MATCH(TRUE, ISNUMBER(SEARCH(K$40, 'AC and RGM only'!$D$2:$J$2)), 0))} -> 2.75 | M48: {=INDEX('AC and RGM only'!$N4:$T153, MATCH(TRUE, ISNUMBER(SEARCH($B$48, 'AC and RGM only'!$L4:$L153)), 0), MATCH(TRUE, ISNUMBER(SEARCH(M$40, 'AC and RGM only'!$D$2:$J$2)), 0))} -> 2.19 | O48: {=INDEX('AC and RGM only'!$N4:$T153, MATCH(TRUE, ISNUMBER(SEARCH($B$48, 'AC and RGM only'!$L4:$L153)), 0), MATCH(TRUE, ISNUMBER(SEARCH(O$40, 'AC and RGM only'!$D$2:$J$2)), 0))} -> 2.75 | R48: =AVERAGE(C48:O48) -> 1.8042857
...

Sheet DRY
F2: DRY STOCK BUILD TO GUIDE | M2: MMX item codes
B3: ORDER FORM CODE
E5: PER PACK | F5: ITEM | G5: 1 DAY USAGE | H5: ON HAND | I5: DAYS HOLDING | J5: ON ORDER | K5: 10 DAY BUILD TO | L5: NEED
B6: 100457 | C6: SAUCE FIRE 10X1KG | E6: 10 | F6: FIRE SAUCE | G6: =AVERAGE(_xlfn.XLOOKUP($B6,'AC and RGM only'!$K$1:$K$150,'AC and RGM only'!$N$1:$T$150)) -> 0.061428571 | H6: =VALUE((_xlfn.XLOOKUP("*"&($C6)&"*",'STOCK ON HAND'!$F$1:$F$200,'STOCK ON HAND'!$H$1:$H$200,,2))/$E6) -> 0.611 | I6: =IF($G6=0,0,($H6*1/$G6)) -> 9.9465116 | J6: =SUMIFS('STOCK ON ORDER'!$L$1:$L$200,'STOCK ON ORDER'!$H$1:$H$200,VALUE($M6)) -> 0 | K6: =G6*10 -> 0.61428571 | L6: =IF(I6>10,0,IFERROR(MAX(0,K6-H6-J6),0)) -> 0.0032857143 | M6: 100457
B7: 37995 | C7: BAG CHIPS LARGE | E7: 3000 | F7: LARGE CHIP BAGS | G7: =AVERAGE(_xlfn.XLOOKUP($B7,'AC and RGM only'!$K$1:$K$150,'AC and RGM only'!$N$1:$T$150)) -> 0.032857143 | H7: =VALUE((_xlfn.XLOOKUP("*"&($C7)&"*",'STOCK ON HAND'!$F$1:$F$200,'STOCK ON HAND'!$H$1:$H$200,,2))/$E7) -> 0.77933333 | I7: =IF($G7=0,0,($H7*1/$G7)) -> 23.718841 | J7: =SUMIFS('STOCK ON ORDER'!$L$2:$L$200,'STOCK ON ORDER'!$H$2:$H$200,$M7) -> 0 | K7: =G7*10 -> 0.32857143 | L7: =IF(I7>10,0,IFERROR(MAX(0,K7-H7-J7),0)) -> 0 | M7: 39944A
B8: 37993 | C8: BAG CHIPS REGULAR | E8: 3000 | F8: REGULAR CHIP BAGS | G8: =AVERAGE(_xlfn.XLOOKUP($B8,'AC and RGM only'!$K$1:$K$150,'AC and RGM only'!$N$1:$T$150)) -> 0.048571429 | H8: =VALUE((_xlfn.XLOOKUP("*"&($C8)&"*",'STOCK ON HAND'!$F$1:$F$200,'STOCK ON HAND'!$H$1:$H$200,,2))/$E8) -> 0.31983333 | I8: =IF($G8=0,0,($H8*1/$G8)) -> 6.5848039 | J8: =SUMIFS('STOCK ON ORDER'!$L$2:$L$200,'STOCK ON ORDER'!$H$2:$H$200,$M8) -> 1 | K8: =G8*10 -> 0.48571429 | L8: =IF(I8>10,0,IFERROR(MAX(0,K8-H8-J8),0)) -> 0 | M8: 39943A
B9: 37893 | C9: BAG CRUNCHWRAP | E9: 2000 | F9: CRUNCHWRAP BAGS | G9: =AVERAGE(_xlfn.XLOOKUP($B9,'AC and RGM only'!$K$1:$K$150,'AC and RGM only'!$N$1:$T$150)) -> 0.058571429 | H9: =VALUE((_xlfn.XLOOKUP("*"&($C9)&"*",'STOCK ON HAND'!$F$1:$F$200,'STOCK ON HAND'!$H$1:$H$200,,2))/$E9) -> 0.5005 | I9: =IF($G9=0,0,($H9*1/$G9)) -> 8.545122 | J9: =SUMIFS('STOCK ON ORDER'!$L$2:$L$200,'STOCK ON ORDER'!$H$2:$H$200,VALUE($M9)) -> 1 | K9: =G9*10 -> 0.58571429 | L9: =IF(I9>10,0,IFERROR(MAX(0,K9-H9-J9),0)) -> 0 | M9: 39942
B10: 37997 | C10: BAG NACHO CHIPS LARGE | E10: 2000 | F10: NACHO CHIP BAGS | G10: =AVERAGE(_xlfn.XLOOKUP($B10,'AC and RGM only'!$K$1:$K$150,'AC and RGM only'!$N$1:$T$150)) -> 0.052857143 | H10: =VALUE((_xlfn.XLOOKUP("*"&($C10)&"*",'STOCK ON HAND'!$F$1:$F$200,'STOCK ON HAND'!$H$1:$H$200,,2))/$E10) -> 0.8555 | I10: =IF($G10=0,0,($H10*1/$G10)) -> 16.185135 | J10: =SUMIFS('STOCK ON ORDER'!$L$2:$L$200,'STOCK ON ORDER'!$H$2:$H$200,VALUE($M10)) -> 0 | K10: =G10*10 -> 0.52857143 | L10: =IF(I10>10,0,IFERROR(MAX(0,K10-H10-J10),0)) -> 0 | M10: 39945
B11: 37991 | C11: BAG TAKEAWAY BROWN LARGE 2 | E11: 250 | F11: LARGE TAKEAWAY BAGS | G11: =AVERAGE(_xlfn.XLOOKUP($B11,'AC and RGM only'!$K$1:$K$150,'AC and RGM only'!$N$1:$T$150)) -> 0.20142857 | H11: =VALUE((_xlfn.XLOOKUP("*"&($C11)&"*",'STOCK ON HAND'!$F$1:$F$200,'STOCK ON HAND'!$H$1:$H$200,,2))/$E11) -> 1.00224 | I11: =IF($G11=0,0,($H11*1/$G11)) -> 4.9756596 | J11: =SUMIFS('STOCK ON ORDER'!$L$2:$L$200,'STOCK ON ORDER'!$H$2:$H$200,VALUE($M11)) -> 1 | K11: =G11*10 -> 2.0142857 | L11: =IF(I11>10,0,IFERROR(MAX(0,K11-H11-J11),0)) -> 0.012045714 | M11: 37991
B12: 37989 | C12: BAG TAKEAWAY BROWN MEDIUM | E12: 1000 | F12: MEDIUM TAKEAWAY BAGS | G12: =AVERAGE(_xlfn.XLOOKUP($B12,'AC and RGM only'!$K$1:$K$150,'AC and RGM only'!$N$1:$T$150)) -> 0.22571429 | H12: =VALUE((_xlfn.XLOOKUP("*"&($C12)&"*",'STOCK ON HAND'!$F$1:$F$200,'STOCK ON HAND'!$H$1:$H$200,,2))/$E12) -> 1.75085 | I12: =IF($G12=0,0,($H12*1/$G12)) -> 7.7569304 | J12: =SUMIFS('STOCK ON ORDER'!$L$2:$L$200,'STOCK ON ORDER'!$H$2:$H$200,VALUE($M12)) -> 1 | K12: =G12*10 -> 2.2571429 | L12: =IF(I12>10,0,IFERROR(MAX(0,K12-H12-J12),0)) -> 0 | M12: 37989
B13: 38892 | C13: BIG BELL BOX 2 | E13: 250 | F13: BIG BELL BOX | G13: =AVERAGE(_xlfn.XLOOKUP($B13,'AC and RGM only'!$K$1:$K$150,'AC and RGM only'!$N$1:$T$150)) -> 0.18285714 | H13: =VALUE((_xlfn.XLOOKUP("*"&($C13)&"*",'STOCK ON HAND'!$F$1:$F$200,'STOCK ON HAND'!$H$1:$H$200,,2))/$E13) -> 0.792 | I13: =IF($G13=0,0,($H13*1/$G13)) -> 4.33125 | J13: =SUMIFS('STOCK ON ORDER'!$L$2:$L$200,'STOCK ON ORDER'!$H$2:$H$200,VALUE($M13)) -> 3 | K13: =G13*20 -> 3.6571429 | L13: =IF(I13>10,0,IFERROR(MAX(0,K13-H13-J13),0)) -> 0 | M13: 38892
B14: 37872 | C14: CANTINA BROWN BOX | E14: 200 | F14: CANTINA BOX | G14: =AVERAGE(_xlfn.XLOOKUP($B14,'AC and RGM only'!$K$1:$K$150,'AC and RGM only'!$N$1:$T$150)) -> 0.18857143 | H14: =VALUE((_xlfn.XLOOKUP("*"&($C14)&"*",'STOCK ON HAND'!$F$1:$F$200,'STOCK ON HAND'!$H$1:$H$200,,2))/$E14) -> 1.145 | I14: =IF($G14=0,0,($H14*1/$G14)) -> 6.0719697 | J14: =SUMIFS('STOCK ON ORDER'!$L$2:$L$200,'STOCK ON ORDER'!$H$2:$H$200,VALUE($M14)) -> 1 | K14: =G14*10 -> 1.8857143 | L14: =IF(I14>10,0,IFERROR(MAX(0,K14-H14-J14),0)) -> 0 | M14: 40014
B15: 38352 | C15: CINNAMON TWISTS | E15: 10 | F15: CINNAMON TWISTS | G15: =AVERAGE(_xlfn.XLOOKUP($B15,'AC and RGM only'!$K$1:$K$150,'AC and RGM only'!$N$1:$T$150)) -> 0.0071428571 | H15: =VALUE((_xlfn.XLOOKUP("*"&($C15)&"*",'STOCK ON HAND'!$F$1:$F$200,'STOCK ON HAND'!$H$1:$H$200,,2))/$E15) -> 0.055 | I15: =IF($G15=0,0,($H15*1/$G15)) -> 7.7 | J15: =SUMIFS('STOCK ON ORDER'!$L$2:$L$200,'STOCK ON ORDER'!$H$2:$H$200,$M15) -> 0 | K15: =G15*10 -> 0.071428571 | L15: =IF(I15>10,0,IFERROR(MAX(0,K15-H15-J15),0)) -> 0.016428571 | M15: 40062A
B16: 37378 | C16: CUP FCB 590 ML CH | E16: 1000 | F16: FROZEN CUPS | G16: =AVERAGE(_xlfn.XLOOKUP($B16,'AC and RGM only'!$K$1:$K$150,'AC and RGM only'!$N$1:$T$150)) -> 0.015714286 | H16: =VALUE((_xlfn.XLOOKUP("*"&($C16)&"*",'STOCK ON HAND'!$F$1:$F$200,'STOCK ON HAND'!$H$1:$H$200,,2))/$E16) -> 0.112 | I16: =IF($G16=0,0,($H16*1/$G16)) -> 7.1272727 | J16: =SUMIFS('STOCK ON ORDER'!$L$2:$L$200,'STOCK ON ORDER'!$H$2:$H$200,VALUE($M16)) -> 1 | K16: =G16*10 -> 0.15714286 | L16: =IF(I16>10,0,IFERROR(MAX(0,K16-H16-J16),0)) -> 0 | M16: 507876
B17: 37856 | C17: CUP POSTMIX LARGE | E17: 1000 | F17: LARGE CUPS | G17: =AVERAGE(_xlfn.XLOOKUP($B17,'AC and RGM only'!$K$1:$K$150,'AC and RGM only'!$N$1:$T$150)) -> 0.068571429 | H17: =VALUE((_xlfn.XLOOKUP("*"&($C17)&"*",'STOCK ON HAND'!$F$1:$F$200,'STOCK ON HAND'!$H$1:$H$200,,2))/$E17) -> 1.023 | I17: =IF($G17=0,0,($H17*1/$G17)) -> 14.91875 | J17: =SUMIFS('STOCK ON ORDER'!$L$2:$L$200,'STOCK ON ORDER'!$H$2:$H$200,VALUE($M17)) -> 0 | K17: =G17*10 -> 0.68571429 | L17: =IF(I17>10,0,IFERROR(MAX(0,K17-H17-J17),0)) -> 0 | M17: 38891
B18: 37854 | C18: CUP POSTMIX REGULAR | E18: 1000 | F18: REGULAR CUPS | G18: =AVERAGE(_xlfn.XLOOKUP($B18,'AC and RGM only'!$K$1:$K$150,'AC and RGM only'!$N$1:$T$150)) -> 0.10571429 | H18: =VALUE((_xlfn.XLOOKUP("*"&($C18)&"*",'STOCK ON HAND'!$F$1:$F$200,'STOCK ON HAND'!$H$1:$H$200,,2))/$E18) -> 0.614 | I18: =IF($G18=0,0,($H18*1/$G18)) -> 5.8081081 | J18: =SUMIFS('STOCK ON ORDER'!$L$2:$L$200,'STOCK ON ORDER'!$H$2:$H$200,VALUE($M18)) -> 1 | K18: =G18*10 -> 1.0571429 | L18: =IF(I18>10,0,IFERROR(MAX(0,K18-H18-J18),0)) -> 0 | M18: 38890
B19: 11172 | C19: DESSERT CHOCETTES | E19: 5 | F19: CHOC CHIPS | G19: =AVERAGE(_xlfn.XLOOKUP($B19,'AC and RGM only'!$K$1:$K$150,'AC and RGM only'!$N$1:$T$150)) -> 0.06 | H19: =VALUE((_xlfn.XLOOKUP("*"&($C19)&"*",'STOCK ON HAND'!$F$1:$F$200,'STOCK ON HAND'!$H$1:$H$200,,2))/$E19) -> 0.726 | I19: =IF($G19=0,0,($H19*1/$G19)) -> 12.1 | J19: =SUMIFS('STOCK ON ORDER'!$L$2:$L$200,'STOCK ON ORDER'!$H$2:$H$200,VALUE($M19)) -> 0 | K19: =G19*10 -> 0.6 | L19: =IF(I19>10,0,IFERROR(MAX(0,K19-H19-J19),0)) -> 0 | M19: 38088
B20: 20295 | C20: JALAPENO | E20: =6*2.3 -> 13.8 | F20: JALAPENOS | G20: =AVERAGE(_xlfn.XLOOKUP($B20,'AC and RGM only'!$K$1:$K$150,'AC and RGM only'!$N$1:$T$150)) -> 0.0057142857 | H20: =VALUE((_xlfn.XLOOKUP("*"&($C20)&"*",'STOCK ON HAND'!$F$1:$F$200,'STOCK ON HAND'!$H$1:$H$200,,2))/$E20) -> 0.64855072 | I20: =IF($G20=0,0,($H20*1/$G20)) -> 113.49638 | J20: =SUMIFS('STOCK ON ORDER'!$L$2:$L$200,'STOCK ON ORDER'!$H$2:$H$200,VALUE($M20)) -> 0 | K20: =G20*10 -> 0.057142857 | L20: =IF(I20>10,0,IFERROR(MAX(0,K20-H20-J20),0)) -> 0 | M20: 40003
B21: 13735 | C21: LID POSTMIX | E21: 1000 | F21: LIDS POSTMIX | G21: =AVERAGE(_xlfn.XLOOKUP($B21,'AC and RGM only'!$K$1:$K$150,'AC and RGM only'!$N$1:$T$150)) -> 0.17142857 | H21: =VALUE((_xlfn.XLOOKUP("*"&($C21)&"*",'STOCK ON HAND'!$F$1:$F$200,'STOCK ON HAND'!$H$1:$H$200,,2))/$E21) -> 2.037 | I21: =IF($G21=0,0,($H21*1/$G21)) -> 11.8825 | J21: =SUMIFS('STOCK ON ORDER'!$L$2:$L$200,'STOCK ON ORDER'!$H$2:$H$200,VALUE($M21)) -> 0 | K21: =G21*10 -> 1.7142857 | L21: =IF(I21>10,0,IFERROR(MAX(0,K21-H21-J21),0)) -> 0 | M21: 38894
B22: 37380 | C22: LID FCB DOME 590 ML CH | E22: 1000 | F22: LIDS FROZEN | G22: =AVERAGE(_xlfn.XLOOKUP($B22,'AC and RGM only'!$K$1:$K$150,'AC and RGM only'!$N$1:$T$150)) -> 0.015714286 | H22: =VALUE((_xlfn.XLOOKUP("*"&($C22)&"*",'STOCK ON HAND'!$F$1:$F$200,'STOCK ON HAND'!$H$1:$H$200,,2))/$E22) -> 1.512 | I22: =IF($G22=0,0,($H22*1/$G22)) -> 96.218182 | J22: =SUMIFS('STOCK ON ORDER'!$L$2:$L$200,'STOCK ON ORDER'!$H$2:$H$200,VALUE($M22)) -> 0 | K22: =G22*10 -> 0.15714286 | L22: =IF(I22>10,0,IFERROR(MAX(0,K22-H22-J22),0)) -> 0 | M22: 507877
B23: 36549 | C23: NAPKINS BROWN RECYCLE | E23: 6000 | F23: NAPKINS | G23: =AVERAGE(_xlfn.XLOOKUP($B23,'AC and RGM only'!$K$1:$K$150,'AC and RGM only'!$N$1:$T$150)) -> 0.11285714 | H23: =VALUE((_xlfn.XLOOKUP("*"&($C23)&"*",'STOCK ON HAND'!$F$1:$F$200,'STOCK ON HAND'!$H$1:$H$200,,2))/$E23) -> 0.30533333 | I23: =IF($G23=0,0,($H23*1/$G23)) -> 2.7054852 | J23: =SUMIFS('STOCK ON ORDER'!$L$2:$L$200,'STOCK ON ORDER'!$H$2:$H$200,VALUE($M23)) -> 1 | K23: =G23*10 -> 1.1285714 | L23: =IF(I23>10,0,IFERROR(MAX(0,K23-H23-J23),0)) -> 0 | M23: 38050
B24: 37915 | C24: RICE LONG GRAIN WHITE | E24: 10 | F24: RICE | G24: =AVERAGE(_xlfn.XLOOKUP($B24,'AC and RGM only'!$K$1:$K$150,'AC and RGM only'!$N$1:$T$150)) -> 0.32285714 | H24: =VALUE((_xlfn.XLOOKUP("*"&($C24)&"*",'STOCK ON HAND'!$F$1:$F$200,'STOCK ON HAND'!$H$1:$H$200,,2))/$E24) -> 1.167 | I24: =IF($G24=0,0,($H24*1/$G24)) -> 3.6146018 | J24: =SUMIFS('STOCK ON ORDER'!$L$2:$L$200,'STOCK ON ORDER'!$H$2:$H$200,$M24) -> 2 | K24: =G24*10 -> 3.2285714 | L24: =IF(I24>10,0,IFERROR(MAX(0,K24-H24-J24),0)) -> 0.061571429 | M24: 37915A
B25: 37870 | C25: SAUCE CHILLI MILD | E25: 10 | F25: MILD SAUCE | G25: =AVERAGE(_xlfn.XLOOKUP($B25,'AC and RGM only'!$K$1:$K$150,'AC and RGM only'!$N$1:$T$150)) -> 0.19285714 | H25: =VALUE((_xlfn.XLOOKUP("*"&($C25)&"*",'STOCK ON HAND'!$F$1:$F$200,'STOCK ON HAND'!$H$1:$H$200,,2))/$E25) -> 1.349 | I25: =IF($G25=0,0,($H25*1/$G25)) -> 6.9948148 | J25: =SUMIFS('STOCK ON ORDER'!$L$2:$L$200,'STOCK ON ORDER'!$H$2:$H$200,VALUE($M25)) -> 1 | K25: =G25*10 -> 1.9285714 | L25: =IF(I25>10,0,IFERROR(MAX(0,K25-H25-J25),0)) -> 0 | M25: 37870
B26: 37883 | C26: SAUCE CHOCOLATE DA VINCI | E26: 6 | F26: CHOC SAUCE | G26: =AVERAGE(_xlfn.XLOOKUP($B26,'AC and RGM only'!$K$1:$K$150,'AC and RGM only'!$N$1:$T$150)) -> 0.038571429 | H26: =VALUE((_xlfn.XLOOKUP("*"&($C26)&"*",'STOCK ON HAND'!$F$1:$F$200,'STOCK ON HAND'!$H$1:$H$200,,2))/$E26) -> 0.895 | I26: =IF($G26=0,0,($H26*1/$G26)) -> 23.203704 | J26: =SUMIFS('STOCK ON ORDER'!$L$2:$L$200,'STOCK ON ORDER'!$H$2:$H$200,VALUE($M26)) -> 0 | K26: =G26*10 -> 0.38571429 | L26: =IF(I26>10,0,IFERROR(MAX(0,K26-H26-J26),0)) -> 0 | M26: 38163
B27: 37883 | C27: SAUCE CHOCOLATE DA VINCI | E27: 6 | F27: CHOC SAUCE | G27: =AVERAGE(_xlfn.XLOOKUP($B27,'AC and RGM only'!$K$1:$K$150,'AC and RGM only'!$N$1:$T$150)) -> 0.038571429 | H27: =VALUE((_xlfn.XLOOKUP("*"&($C27)&"*",'STOCK ON HAND'!$F$1:$F$200,'STOCK ON HAND'!$H$1:$H$200,,2))/$E27) -> 0.895 | I27: =IF($G27=0,0,($H27*1/$G27)) -> 23.203704 | J27: =SUMIFS('STOCK ON ORDER'!$L$2:$L$200,'STOCK ON ORDER'!$H$2:$H$200,$M27) -> 0 | K27: =G27*10 -> 0.38571429 | L27: =IF(I27>10,0,IFERROR(MAX(0,K27-H27-J27),0)) -> 0 | M27: 38163A
B28: 37907 | C28: SEASONING MEXICAN RICE | E28: 10 | F28: MEX SEASONING | G28: =AVERAGE(_xlfn.XLOOKUP($B28,'AC and RGM only'!$K$1:$K$150,'AC and RGM only'!$N$1:$T$150)) -> 0.10857143 | H28: =VALUE((_xlfn.XLOOKUP("*"&($C28)&"*",'STOCK ON HAND'!$F$1:$F$200,'STOCK ON HAND'!$H$1:$H$200,,2))/$E28) -> 1.123 | I28: =IF($G28=0,0,($H28*1/$G28)) -> 10.343421 | J28: =SUMIFS('STOCK ON ORDER'!$L$2:$L$200,'STOCK ON ORDER'!$H$2:$H$200,VALUE($M28)) -> 0 | K28: =G28*10 -> 1.0857143 | L28: =IF(I28>10,0,IFERROR(MAX(0,K28-H28-J28),0)) -> 0 | M28: 39054
B29: 39185 | C29: STRAW PAPER KFC | E29: 4000 | F29: STRAWS | G29: =AVERAGE(_xlfn.XLOOKUP($B29,'AC and RGM only'!$K$1:$K$150,'AC and RGM only'!$N$1:$T$150)) -> 0.048571429 | H29: =VALUE((_xlfn.XLOOKUP("*"&($C29)&"*",'STOCK ON HAND'!$F$1:$F$200,'STOCK ON HAND'!$H$1:$H$200,,2))/$E29) -> 1.081 | I29: =IF($G29=0,0,($H29*1/$G29)) -> 22.255882 | J29: =SUMIFS('STOCK ON ORDER'!$L$2:$L$200,'STOCK ON ORDER'!$H$2:$H$200,VALUE($M29)) -> 0 | K29: =G29*10 -> 0.48571429 | L29: =IF(I29>10,0,IFERROR(MAX(0,K29-H29-J29),0)) -> 0 | M29: 507516
B30: 34210 | C30: SUGAR CINNAMON 5KG | E30: =5*2.5 -> 12.5 | F30: CINNAMON SUGAR | G30: =AVERAGE(_xlfn.XLOOKUP($B30,'AC and RGM only'!$K$1:$K$150,'AC and RGM only'!$N$1:$T$150)) -> 0.0085714286 | H30: =VALUE((_xlfn.XLOOKUP("*"&($C30)&"*",'STOCK ON HAND'!$F$1:$F$200,'STOCK ON HAND'!$H$1:$H$200,,2))/$E30) -> 0.5784 | I30: =IF($G30=0,0,($H30*1/$G30)) -> 67.48 | J30: =SUMIFS('STOCK ON ORDER'!$L$2:$L$200,'STOCK ON ORDER'!$H$2:$H$200,VALUE($M30)) -> 0 | K30: =G30*10 -> 0.085714286 | L30: =IF(I30>10,0,IFERROR(MAX(0,K30-H30-J30),0)) -> 0 | M30: 40037
B31: 39744 | C31: DIPPING CUP 60ML | E31: 1000 | F31: DIPPING CUPS | G31: =AVERAGE(_xlfn.XLOOKUP($B31,'AC and RGM only'!$K$1:$K$150,'AC and RGM only'!$N$1:$T$150)) -> 0.16142857 | H31: =VALUE((_xlfn.XLOOKUP("*"&($C31)&"*",'STOCK ON HAND'!$F$1:$F$200,'STOCK ON HAND'!$H$1:$H$200,,2))/$E31) -> 0.87 | I31: =IF($G31=0,0,($H31*1/$G31)) -> 5.3893805 | J31: =SUMIFS('STOCK ON ORDER'!$L$2:$L$200,'STOCK ON ORDER'!$H$2:$H$200,VALUE($M31)) -> 1 | K31: =G31*10 -> 1.6142857 | L31: =IF(I31>10,0,IFERROR(MAX(0,K31-H31-J31),0)) -> 0 | M31: 39744
B32: 39746 | C32: LID CLEAR 60ML DIPPING CUP | E32: 1000 | F32: DIPPING CUP LIDS | G32: =AVERAGE(_xlfn.XLOOKUP($B32,'AC and RGM only'!$K$1:$K$150,'AC and RGM only'!$N$1:$T$150)) -> 0.16142857 | H32: =VALUE((_xlfn.XLOOKUP("*"&($C32)&"*",'STOCK ON HAND'!$F$1:$F$200,'STOCK ON HAND'!$H$1:$H$200,,2))/$E32) -> 1.4 | I32: =IF($G32=0,0,($H32*1/$G32)) -> 8.6725664 | J32: =SUMIFS('STOCK ON ORDER'!$L$2:$L$200,'STOCK ON ORDER'!$H$2:$H$200,VALUE($M32)) -> 0 | K32: =G32*10 -> 1.6142857 | L32: =IF(I32>10,0,IFERROR(MAX(0,K32-H32-J32),0)) -> 0.21428571 | M32: 39746
B33: 39769 | C33: WOODEN FORK | E33: 1000 | F33: FORKS | G33: =AVERAGE(_xlfn.XLOOKUP($B33,'AC and RGM only'!$K$1:$K$150,'AC and RGM only'!$N$1:$T$150)) -> 0.035714286 | H33: =VALUE((_xlfn.XLOOKUP("*"&($C33)&"*",'STOCK ON HAND'!$F$1:$F$200,'STOCK ON HAND'!$H$1:$H$200,,2))/$E33) -> 0.319 | I33: =IF($G33=0,0,($H33*1/$G33)) -> 8.932 | J33: =SUMIFS('STOCK ON ORDER'!$L$2:$L$200,'STOCK ON ORDER'!$H$2:$H$200,VALUE($M33)) -> 0 | K33: =G33*10 -> 0.35714286 | L33: =IF(I33>10,0,IFERROR(MAX(0,K33-H33-J33),0)) -> 0.038142857 | M33: 39748
B34: 13529 | C34: TRAYS DRINKS 4 CUP | E34: 100 | F34: DRINK TRAYS | G34: 0.01 | H34: =VALUE((_xlfn.XLOOKUP("*"&($C34)&"*",'STOCK ON HAND'!$F$1:$F$200,'STOCK ON HAND'!$H$1:$H$200,,2))/$E34) -> -0.313 | I34: =IF($G34=0,0,($H34*1/$G34)) -> -31.3 | J34: =SUMIFS('STOCK ON ORDER'!$L$2:$L$200,'STOCK ON ORDER'!$H$2:$H$200,VALUE($M34)) -> 0 | K34: =G34*10 -> 0.1 | L34: =IF(I34>10,0,IFERROR(MAX(0,K34-H34-J34),0)) -> 0.413 | M34: 505798
B35: 37901 | C35: WRAP LARGE WHITE PRINTED | E35: 3000 | F35: LARGE WRAPS | G35: =AVERAGE(_xlfn.XLOOKUP($B35,'AC and RGM only'!$K$1:$K$150,'AC and RGM only'!$N$1:$T$150)) -> 0.091428571 | H35: =VALUE((_xlfn.XLOOKUP("*"&($C35)&"*",'STOCK ON HAND'!$F$1:$F$200,'STOCK ON HAND'!$H$1:$H$200,,2))/$E35) -> 0.23733333 | I35: =IF($G35=0,0,($H35*1/$G35)) -> 2.5958333 | J35: =SUMIFS('STOCK ON ORDER'!$L$2:$L$200,'STOCK ON ORDER'!$H$2:$H$200,VALUE($M35)) -> 1 | K35: =G35*10 -> 0.91428571 | L35: =IF(I35>10,0,IFERROR(MAX(0,K35-H35-J35),0)) -> 0 | M35: 37901
B36: 37921 | C36: WRAP SMALL WHITE PRINTED | E36: 3000 | F36: SMALL WRAPS | G36: =AVERAGE(_xlfn.XLOOKUP($B36,'AC and RGM only'!$K$1:$K$150,'AC and RGM only'!$N$1:$T$150)) -> 0.054285714 | H36: =VALUE((_xlfn.XLOOKUP("*"&($C36)&"*",'STOCK ON HAND'!$F$1:$F$200,'STOCK ON HAND'!$H$1:$H$200,,2))/$E36) -> 1.3376667 | I36: =IF($G36=0,0,($H36*1/$G36)) -> 24.641228 | J36: =SUMIFS('STOCK ON ORDER'!$L$2:$L$200,'STOCK ON ORDER'!$H$2:$H$200,VALUE($M36)) -> 0 | K36: =G36*10 -> 0.54285714 | L36: =IF(I36>10,0,IFERROR(MAX(0,K36-H36-J36),0)) -> 0 | M36: 37921
B37: 37999 | C37: WRAP WASTE WHITE UNPRINTED | E37: 5000 | F37: WASTE WRAPS | G37: =AVERAGE(_xlfn.XLOOKUP($B37,'AC and RGM only'!$K$1:$K$150,'AC and RGM only'!$N$1:$T$150)) -> 0.10142857 | H37: =VALUE((_xlfn.XLOOKUP("*"&($C37)&"*",'STOCK ON HAND'!$F$1:$F$200,'STOCK ON HAND'!$H$1:$H$200,,2))/$E37) -> 1.4522 | I37: =IF($G37=0,0,($H37*1/$G37)) -> 14.317465 | J37: =SUMIFS('STOCK ON ORDER'!$L$2:$L$200,'STOCK ON ORDER'!$H$2:$H$200,VALUE($M37)) -> 0 | K37: =G37*10 -> 1.0142857 | L37: =IF(I37>10,0,IFERROR(MAX(0,K37-H37-J37),0)) -> 0 | M37: 37999

Sheet FRIDGE & FREEZER
E2: FREEZER BUILD TO GUIDE | L2: MMX item codes
B3: ORDER FORM CODE
D5: PER PACK | E5: ITEM | F5: 1 DAY USAGE | G5: ON HAND | H5: DAYS HOLDING | I5: ON ORDER | J5: 10 DAY BUILD TO | K5: NEED
A6: =IFERROR(VLOOKUP($B6,'AC and RGM only'!$K$2:$L$250,2,FALSE),"") -> CHICKEN CRISPY | B6: 40303 | D6: =6*41 -> 246 | E6: CRISPY CHICKEN | F6: =AVERAGE(_xlfn.XLOOKUP($B6,'AC and RGM only'!$K$1:$K$150,'AC and RGM only'!$N$1:$T$150)) -> 0.35857143 | G6: {=_xlfn.XLOOKUP($B6,VALUE('STOCK ON HAND'!$E$1:$E$200),'STOCK ON HAND'!$H$1:$H$200,0)/D6} -> 1.1300813 | H6: =IF($F6=0,0,($G6*1/$F6)) -> 3.1516212 | I6: =SUMIFS('STOCK ON ORDER'!$L$2:$L$200,'STOCK ON ORDER'!$H$2:$H$200,VALUE($L6)) -> 2 | J6: =F6*10 -> 3.5857143 | K6: =IF(H6>10,0,IFERROR(MAX(0,J6-G6-I6),0)) -> 0.45563298 | L6: 40303
A7: =IFERROR(VLOOKUP($B7,'AC and RGM only'!$K$2:$L$250,2,FALSE),"") -> BEANS BLACK COOKED | B7: 37862 | D7: 12 | E7: BLACK BEAN | F7: =AVERAGE(_xlfn.XLOOKUP($B7,'AC and RGM only'!$K$1:$K$150,'AC and RGM only'!$N$1:$T$150)) -> 0.60285714 | G7: {=_xlfn.XLOOKUP($B7,VALUE('STOCK ON HAND'!$E$1:$E$200),'STOCK ON HAND'!$H$1:$H$200,0)/D7} -> 0.4 | H7: =IF($F7=0,0,($G7*1/$F7)) -> 0.66350711 | I7: =SUMIFS('STOCK ON ORDER'!$L$2:$L$200,'STOCK ON ORDER'!$H$2:$H$200,$L7) -> 5 | J7: =F7*10 -> 6.0285714 | K7: =IF(H7>10,0,IFERROR(MAX(0,J7-G7-I7),0)) -> 0.62857143 | L7: 38246A
A8: =IFERROR(VLOOKUP($B8,'AC and RGM only'!$K$2:$L$250,2,FALSE),"") -> CHIP NACHO CORN | B8: 37887 | D8: 4.5 | E8: NACHO CHIPS (Inc Thawed) | F8: =AVERAGE(_xlfn.XLOOKUP($B8,'AC and RGM only'!$K$1:$K$150,'AC and RGM only'!$N$1:$T$150)) -> 0.66 | G8: {=_xlfn.XLOOKUP($B8,VALUE('STOCK ON HAND'!$E$1:$E$200),'STOCK ON HAND'!$H$1:$H$200,0)/D8} -> 3.7066667 | H8: =IF($F8=0,0,($G8*1/$F8)) -> 5.6161616 | I8: =SUMIFS('STOCK ON ORDER'!$L$2:$L$200,'STOCK ON ORDER'!$H$2:$H$200,VALUE($L8)) -> 5 | J8: =F8*13 -> 8.58 | K8: =IF(H8>13,0,IFERROR(MAX(0,J8-G8-I8),0)) -> 0 | L8: 39009
A9: =IFERROR(VLOOKUP($B9,'AC and RGM only'!$K$2:$L$250,2,FALSE),"") -> CHURROS MINI | B9: 37897 | D9: 72 | E9: CHURROS | F9: =AVERAGE(_xlfn.XLOOKUP($B9,'AC and RGM only'!$K$1:$K$150,'AC and RGM only'!$N$1:$T$150)) -> 0.39428571 | G9: {=_xlfn.XLOOKUP($B9,VALUE('STOCK ON HAND'!$E$1:$E$200),'STOCK ON HAND'!$H$1:$H$200,0)/D9} -> 3.1944444 | H9: =IF($F9=0,0,($G9*1/$F9)) -> 8.1018519 | I9: =SUMIFS('STOCK ON ORDER'!$L$2:$L$200,'STOCK ON ORDER'!$H$2:$H$200,VALUE($L9)) -> 0 | J9: =F9*10 -> 3.9428571 | K9: =IF(H9>10,0,IFERROR(MAX(0,J9-G9-I9),0)) -> 0.7484127 | L9: 37897
A10: =IFERROR(VLOOKUP($B10,'AC and RGM only'!$K$2:$L$250,2,FALSE),"") -> FLATBREAD | B10: 37895 | D10: =24*6 -> 144 | E10: FLAT BREAD (Inc Thawed) | F10: =AVERAGE(_xlfn.XLOOKUP($B10,'AC and RGM only'!$K$1:$K$150,'AC and RGM only'!$N$1:$T$150)) -> 0.64714286 | G10: {=_xlfn.XLOOKUP($B10,VALUE('STOCK ON HAND'!$E$1:$E$200),'STOCK ON HAND'!$H$1:$H$200,0)/D10} -> 3.1388889 | H10: =IF($F10=0,0,($G10*1/$F10)) -> 4.8503802 | I10: =SUMIFS('STOCK ON ORDER'!$L$2:$L$200,'STOCK ON ORDER'!$H$2:$H$200,VALUE($L10)) -> 5 | J10: =F10*13 -> 8.4128571 | K10: =IF(H10>13,0,IFERROR(MAX(0,J10-G10-I10),0)) -> 0.27396825 | L10: 38620
A11: =IFERROR(VLOOKUP($B11,'AC and RGM only'!$K$2:$L$250,2,FALSE),"") -> FRIES SURECRISP | B11: 15049 | D11: 12 | E11: FRIES SUPERCRISP | F11: =AVERAGE(_xlfn.XLOOKUP($B11,'AC and RGM only'!$K$1:$K$150,'AC and RGM only'!$N$1:$T$150)) -> 4.48 | G11: {=_xlfn.XLOOKUP($B11,VALUE('STOCK ON HAND'!$E$1:$E$200),'STOCK ON HAND'!$H$1:$H$200,0)/D11} -> 22.9775 | H11: =IF($F11=0,0,($G11*1/$F11)) -> 5.1289062 | I11: =SUMIFS('STOCK ON ORDER'!$L$2:$L$200,'STOCK ON ORDER'!$H$2:$H$200,VALUE($L11)) -> 28 | J11: =F11*13 -> 58.24 | K11: =IF(H11>10,0,IFERROR(MAX(0,J11-G11-I11),0)) -> 7.2625 | L11: 40109
A12: =IFERROR(VLOOKUP($B12,'AC and RGM only'!$K$2:$L$250,2,FALSE),"") -> GUACAMOLE | B12: 14791 | D12: =6*1.5 -> 9 | E12: GUACAMOLE | F12: =AVERAGE(_xlfn.XLOOKUP($B12,'AC and RGM only'!$K$1:$K$150,'AC and RGM only'!$N$1:$T$150)) -> 0.24 | G12: {=_xlfn.XLOOKUP($B12,VALUE('STOCK ON HAND'!$E$1:$E$200),'STOCK ON HAND'!$H$1:$H$200,0)/D12} -> 1.8077778 | H12: =IF($F12=0,0,($G12*1/$F12)) -> 7.5324074 | I12: =SUMIFS('STOCK ON ORDER'!$L$2:$L$200,'STOCK ON ORDER'!$H$2:$H$200,VALUE($L12)) -> 1 | J12: =F12*10 -> 2.4 | K12: =IF(H12>10,0,IFERROR(MAX(0,J12-G12-I12),0)) -> 0 | L12: 14791
A13: =IFERROR(VLOOKUP($B13,'AC and RGM only'!$K$2:$L$250,2,FALSE),"") -> MEAT BEEF COOKED | B13: 39520 | D13: =8*1.85 -> 14.8 | E13: BEEF (Inc Thawed) | F13: =AVERAGE(_xlfn.XLOOKUP($B13,'AC and RGM only'!$K$1:$K$150,'AC and RGM only'!$N$1:$T$150)) -> 1.5871429 | G13: {=_xlfn.XLOOKUP($B13,VALUE('STOCK ON HAND'!$E$1:$E$200),'STOCK ON HAND'!$H$1:$H$200,0)/D13} -> 7.8587838 | H13: =IF($F13=0,0,($G13*1/$F13)) -> 4.9515289 | I13: =SUMIFS('STOCK ON ORDER'!$L$2:$L$200,'STOCK ON ORDER'!$H$2:$H$200,VALUE($L13)) -> 10 | J13: =F13*13 -> 20.632857 | K13: =IF(H13>13,0,IFERROR(MAX(0,J13-G13-I13),0)) -> 2.7740734 | L13: 39520
A14: =IFERROR(VLOOKUP($B14,'AC and RGM only'!$K$2:$L$250,2,FALSE),"") -> MEAT CHICKEN COOKED | B14: 39139 | D14: 6 | E14: CHICKEN | F14: =AVERAGE(_xlfn.XLOOKUP($B14,'AC and RGM only'!$K$1:$K$150,'AC and RGM only'!$N$1:$T$150)) -> 1.6157143 | G14: {=_xlfn.XLOOKUP($B14,VALUE('STOCK ON HAND'!$E$1:$E$200),'STOCK ON HAND'!$H$1:$H$200,0)/D14} -> 3.83 | H14: =IF($F14=0,0,($G14*1/$F14)) -> 2.3704686 | I14: =SUMIFS('STOCK ON ORDER'!$L$2:$L$200,'STOCK ON ORDER'!$H$2:$H$200,$L14) -> 10 | J14: =F14*10 -> 16.157143 | K14: =IF(H14>10,0,IFERROR(MAX(0,J14-G14-I14),0)) -> 2.3271429 | L14: 39867A
A15: =IFERROR(VLOOKUP($B15,'AC and RGM only'!$K$2:$L$250,2,FALSE),"") -> TORTILLA CORN 6 INCH | B15: 37891 | D15: =12*36 -> 432 | E15: TOSTADAS (Inc Thawed) | F15: =AVERAGE(_xlfn.XLOOKUP($B15,'AC and RGM only'!$K$1:$K$150,'AC and RGM only'!$N$1:$T$150)) -> 0.71714286 | G15: {=_xlfn.XLOOKUP($B15,VALUE('STOCK ON HAND'!$E$1:$E$200),'STOCK ON HAND'!$H$1:$H$200,0)/D15} -> 3.2106481 | H15: =IF($F15=0,0,($G15*1/$F15)) -> 4.4769994 | I15: =SUMIFS('STOCK ON ORDER'!$L$2:$L$200,'STOCK ON ORDER'!$H$2:$H$200,VALUE($L15)) -> 5 | J15: =F15*13 -> 9.3228571 | K15: =IF(H15>13,0,IFERROR(MAX(0,J15-G15-I15),0)) -> 1.112209 | L15: 37891
A16: =IFERROR(VLOOKUP($B16,'AC and RGM only'!$K$2:$L$250,2,FALSE),"") -> TORTILLA FLOUR 10.25INCH | B16: 37923 | D16: =12*12 -> 144 | E16: 10.25" TORTS (Inc Thawed) | F16: =AVERAGE(_xlfn.XLOOKUP($B16,'AC and RGM only'!$K$1:$K$150,'AC and RGM only'!$N$1:$T$150)) -> 0.95857143 | G16: {=_xlfn.XLOOKUP($B16,VALUE('STOCK ON HAND'!$E$1:$E$200),'STOCK ON HAND'!$H$1:$H$200,0)/D16} -> 5.2361111 | H16: =IF($F16=0,0,($G16*1/$F16)) -> 5.462411 | I16: =SUMIFS('STOCK ON ORDER'!$L$2:$L$200,'STOCK ON ORDER'!$H$2:$H$200,VALUE($L16)) -> 6 | J16: =F16*13 -> 12.461429 | K16: =IF(H16>13,0,IFERROR(MAX(0,J16-G16-I16),0)) -> 1.2253175 | L16: 37923
A17: =IFERROR(VLOOKUP($B17,'AC and RGM only'!$K$2:$L$250,2,FALSE),"") -> TORTILLA FLOUR 12INCH | B17: 37925 | D17: 144 | E17: 12" TORTS (Inc Thawed) | F17: =AVERAGE(_xlfn.XLOOKUP($B17,'AC and RGM only'!$K$1:$K$150,'AC and RGM only'!$N$1:$T$150)) -> 0.95857143 | G17: {=_xlfn.XLOOKUP($B17,VALUE('STOCK ON HAND'!$E$1:$E$200),'STOCK ON HAND'!$H$1:$H$200,0)/D17} -> 3.3333333 | H17: =IF($F17=0,0,($G17*1/$F17)) -> 3.4773969 | I17: =SUMIFS('STOCK ON ORDER'!$L$2:$L$200,'STOCK ON ORDER'!$H$2:$H$200,VALUE($L17)) -> 8 | J17: =F17*13 -> 12.461429 | K17: =IF(H17>13,0,IFERROR(MAX(0,J17-G17-I17),0)) -> 1.1280952 | L17: 37925
A18: =IFERROR(VLOOKUP($B18,'AC and RGM only'!$K$2:$L$250,2,FALSE),"") -> TORTILLA FLOUR 6.5INCH | B18: 37927 | D18: =24*12 -> 288 | E18: 6.5" TORTS (Inc Thawed) | F18: =AVERAGE(_xlfn.XLOOKUP($B18,'AC and RGM only'!$K$1:$K$150,'AC and RGM only'!$N$1:$T$150)) -> 0.25142857 | G18: {=_xlfn.XLOOKUP($B18,VALUE('STOCK ON HAND'!$E$1:$E$200),'STOCK ON HAND'!$H$1:$H$200,0)/D18} -> 1.0451389 | H18: =IF($F18=0,0,($G18*1/$F18)) -> 4.1568024 | I18: =SUMIFS('STOCK ON ORDER'!$L$2:$L$200,'STOCK ON ORDER'!$H$2:$H$200,VALUE($L18)) -> 2 | J18: =F18*13 -> 3.2685714 | K18: =IF(H18>13,0,IFERROR(MAX(0,J18-G18-I18),0)) -> 0.22343254 | L18: 37927
E20: FRIDGE BUILD TO GUIDE
D23: PER PACK | E23: ITEM | F23: 1 DAY USAGE | G23: ON HAND | H23: DAYS HOLDING | I23: ON ORDER | J23: 10 DAY BUILD TO | K23: NEED
A24: =IFERROR(VLOOKUP($B24,'AC and RGM only'!$K$2:$L$250,2,FALSE),"") -> CHEESE BLEND MOZZ/CHEDD (PIZZA) SHRED | B24: 37876 | D24: 12 | E24: CHEESE BLEND | F24: =AVERAGE(_xlfn.XLOOKUP($B24,'AC and RGM only'!$K$1:$K$150,'AC and RGM only'!$N$1:$T$150)) -> 0.4 | G24: {=_xlfn.XLOOKUP($B24,VALUE('STOCK ON HAND'!$E$1:$E$200),'STOCK ON HAND'!$H$1:$H$200,0)/D24} -> 0.785 | H24: =IF($F24=0,0,($G24*1/$F24)) -> 1.9625 | I24: =SUMIFS('STOCK ON ORDER'!$L$2:$L$200,'STOCK ON ORDER'!$H$2:$H$200,VALUE($L24)) -> 3 | J24: =F24*10 -> 4 | K24: =IF(H24>10,0,IFERROR(MAX(0,J24-G24-I24),0)) -> 0.215 | L24: 40266
A25: =IFERROR(VLOOKUP($B25,'AC and RGM only'!$K$2:$L$250,2,FALSE),"") -> CHEESE CHEDD ANGEL HAIR/ S'FINE SHRED | B25: 37911 | D25: 12 | E25: ANGEL CHEESE | F25: =AVERAGE(_xlfn.XLOOKUP($B25,'AC and RGM only'!$K$1:$K$150,'AC and RGM only'!$N$1:$T$150)) -> 0.20285714 | G25: {=_xlfn.XLOOKUP($B25,VALUE('STOCK ON HAND'!$E$1:$E$200),'STOCK ON HAND'!$H$1:$H$200,0)/D25} -> 1.2791667 | H25: =IF($F25=0,0,($G25*1/$F25)) -> 6.3057512 | I25: =SUMIFS('STOCK ON ORDER'!$L$2:$L$200,'STOCK ON ORDER'!$H$2:$H$200,VALUE($L25)) -> 1 | J25: =F25*10 -> 2.0285714 | K25: =IF(H25>10,0,IFERROR(MAX(0,J25-G25-I25),0)) -> 0 | L25: 37911
A26: =IFERROR(VLOOKUP($B26,'AC and RGM only'!$K$2:$L$250,2,FALSE),"") -> LAVA SAUCE | B26: 38701 | D26: 10 | E26: LAVA SAUCE | F26: =AVERAGE(_xlfn.XLOOKUP($B26,'AC and RGM only'!$K$1:$K$150,'AC and RGM only'!$N$1:$T$150)) -> 0.075714286 | G26: {=_xlfn.XLOOKUP($B26,VALUE('STOCK ON HAND'!$E$1:$E$200),'STOCK ON HAND'!$H$1:$H$200,0)/D26} -> 0.901 | H26: =IF($F26=0,0,($G26*1/$F26)) -> 11.9 | I26: =SUMIFS('STOCK ON ORDER'!$L$2:$L$200,'STOCK ON ORDER'!$H$2:$H$200,VALUE($L26)) -> 0 | J26: =F26*10 -> 0.75714286 | K26: =IF(H26>10,0,IFERROR(MAX(0,J26-G26-I26),0)) -> 0 | L26: 38701
A27: =IFERROR(VLOOKUP($B27,'AC and RGM only'!$K$2:$L$250,2,FALSE),"") -> OIL FRYING LIQUID CARGILL | B27: 33312 | D27: 15 | E27: FRY OIL | F27: =AVERAGE(_xlfn.XLOOKUP($B27,'AC and RGM only'!$K$1:$K$150,'AC and RGM only'!$N$1:$T$150)) -> 0.53714286 | G27: {=_xlfn.XLOOKUP($B27,VALUE('STOCK ON HAND'!$E$1:$E$200),'STOCK ON HAND'!$H$1:$H$200,0)/D27} -> 6.1553333 | H27: =IF($F27=0,0,($G27*1/$F27)) -> 11.459397 | I27: =SUMIFS('STOCK ON ORDER'!$L$2:$L$200,'STOCK ON ORDER'!$H$2:$H$200,VALUE($L27)) -> 9 | J27: 8 | K27: =IFERROR(MAX(0,J27-G27-I27),0) -> 0 | L27: 507825
A28: =IFERROR(VLOOKUP($B28,'AC and RGM only'!$K$2:$L$250,2,FALSE),"") -> SAUCE CHIPOTLE MAYO 1 | B28: 38493 | D28: 15 | E28: CHIPOTLE MAYO | F28: =AVERAGE(_xlfn.XLOOKUP($B28,'AC and RGM only'!$K$1:$K$150,'AC and RGM only'!$N$1:$T$150)) -> 0.15571429 | G28: {=_xlfn.XLOOKUP($B28,VALUE('STOCK ON HAND'!$E$1:$E$200),'STOCK ON HAND'!$H$1:$H$200,0)/D28} -> 0.538 | H28: =IF($F28=0,0,($G28*1/$F28)) -> 3.4550459 | I28: =SUMIFS('STOCK ON ORDER'!$L$2:$L$200,'STOCK ON ORDER'!$H$2:$H$200,VALUE($L28)) -> 1 | J28: =F28*10 -> 1.5571429 | K28: =IF(H28>10,0,IFERROR(MAX(0,J28-G28-I28),0)) -> 0.019142857 | L28: 38493
A29: =IFERROR(VLOOKUP($B29,'AC and RGM only'!$K$2:$L$250,2,FALSE),"") -> SAUCE CREAMY JALAPENO | B29: 38722 | D29: 10 | E29: CREAMY JALAPENO | F29: =AVERAGE(_xlfn.XLOOKUP($B29,'AC and RGM only'!$K$1:$K$150,'AC and RGM only'!$N$1:$T$150)) -> 0.078571429 | G29: {=_xlfn.XLOOKUP($B29,VALUE('STOCK ON HAND'!$E$1:$E$200),'STOCK ON HAND'!$H$1:$H$200,0)/D29} -> 0.726 | H29: =IF($F29=0,0,($G29*1/$F29)) -> 9.24 | I29: =SUMIFS('STOCK ON ORDER'!$L$2:$L$200,'STOCK ON ORDER'!$H$2:$H$200,VALUE($L29)) -> 0 | J29: =F29*10 -> 0.78571429 | K29: =IF(H29>10,0,IFERROR(MAX(0,J29-G29-I29),0)) -> 0.059714286 | L29: 38722
A30: =IFERROR(VLOOKUP($B30,'AC and RGM only'!$K$2:$L$250,2,FALSE),"") -> SAUCE NACHO CHEESE | B30: 37909 | D30: =6*1.8 -> 10.8 | E30: NACHO CHEESE SAUCE | F30: =AVERAGE(_xlfn.XLOOKUP($B30,'AC and RGM only'!$K$1:$K$150,'AC and RGM only'!$N$1:$T$150)) -> 0.72714286 | G30: {=_xlfn.XLOOKUP($B30,VALUE('STOCK ON HAND'!$E$1:$E$200),'STOCK ON HAND'!$H$1:$H$200,0)/D30} -> 1.7981481 | H30: =IF($F30=0,0,($G30*1/$F30)) -> 2.4728953 | I30: =SUMIFS('STOCK ON ORDER'!$L$2:$L$200,'STOCK ON ORDER'!$H$2:$H$200,VALUE($L30)) -> 5 | J30: =F30*10 -> 7.2714286 | K30: =IF(H30>10,0,IFERROR(MAX(0,J30-G30-I30),0)) -> 0.47328042 | L30: 37909
A31: =IFERROR(VLOOKUP($B31,'AC and RGM only'!$K$2:$L$250,2,FALSE),"") -> SAUCE PICO DE GALLO 100GM | B31: 37913 | D31: 6 | E31: PICO DE GALLO | F31: =AVERAGE(_xlfn.XLOOKUP($B31,'AC and RGM only'!$K$1:$K$150,'AC and RGM only'!$N$1:$T$150)) -> 0.041428571 | G31: {=_xlfn.XLOOKUP($B31,VALUE('STOCK ON HAND'!$E$1:$E$200),'STOCK ON HAND'!$H$1:$H$200,0)/D31} -> 0.45666667 | H31: =IF($F31=0,0,($G31*1/$F31)) -> 11.022989 | I31: =SUMIFS('STOCK ON ORDER'!$L$2:$L$200,'STOCK ON ORDER'!$H$2:$H$200,VALUE($L31)) -> 0 | J31: =F31*10 -> 0.41428571 | K31: =IF(H31>10,0,IFERROR(MAX(0,J31-G31-I31),0)) -> 0 | L31: 37913
A32: =IFERROR(VLOOKUP($B32,'AC and RGM only'!$K$2:$L$250,2,FALSE),"") -> SAUCE ZESTY RANCH 1 | B32: 38414 | D32: 15 | E32: ZESTY RANCH | F32: =AVERAGE(_xlfn.XLOOKUP($B32,'AC and RGM only'!$K$1:$K$150,'AC and RGM only'!$N$1:$T$150)) -> 0.28857143 | G32: {=_xlfn.XLOOKUP($B32,VALUE('STOCK ON HAND'!$E$1:$E$200),'STOCK ON HAND'!$H$1:$H$200,0)/D32} -> 1.1446667 | H32: =IF($F32=0,0,($G32*1/$F32)) -> 3.9666667 | I32: =SUMIFS('STOCK ON ORDER'!$L$2:$L$200,'STOCK ON ORDER'!$H$2:$H$200,VALUE($L32)) -> 2 | J32: =F32*10 -> 2.8857143 | K32: =IF(H32>10,0,IFERROR(MAX(0,J32-G32-I32),0)) -> 0 | L32: 38414

Sheet SCHWEPPES
E2: SCHWEPPES BUILD-TO GUIDE | L2: MMX item codes
B3: ORDER FORM CODE
D5: PER PACK | E5: ITEM | F5: 1 DAY USAGE | G5: ON HAND | H5: DAYS HOLDING | I5: ON ORDER | J5: 10 DAY BUILD TO | K5: NEED
A6: =IFERROR(VLOOKUP($B6,'AC and RGM only'!$K$2:$L$250,2,FALSE),"") -> DRINK WATER SPARKLING 500ML | B6: 100402 | D6: 24 | E6: SPARKLING WATER | F6: =AVERAGE(_xlfn.XLOOKUP($B6,'AC and RGM only'!$K$1:$K$150,'AC and RGM only'!$N$1:$T$150)) -> 0.03 | G6: {=_xlfn.XLOOKUP($B6,VALUE('STOCK ON HAND'!$E$1:$E$200),'STOCK ON HAND'!$H$1:$H$200,0)/D6} -> 0.83333333 | H6: =IF($F6=0,0,($G6*1/$F6)) -> 27.777778 | I6: =SUMIFS('STOCK ON ORDER'!$L$2:$L$200,'STOCK ON ORDER'!$H$2:$H$200,VALUE($L6)) -> 0 | J6: =F6*10 -> 0.3 | K6: =IF(H6>10,0,IFERROR(MAX(0,J6-G6-I6),0)) -> 0 | L6: 10005242
A7: =IFERROR(VLOOKUP($B7,'AC and RGM only'!$K$2:$L$250,2,FALSE),"") -> DRINK RED BULL ED 250ML | B7: 100403 | D7: 24 | E7: RED BULL | F7: =AVERAGE(_xlfn.XLOOKUP($B7,'AC and RGM only'!$K$1:$K$150,'AC and RGM only'!$N$1:$T$150)) -> 0.094285714 | G7: {=_xlfn.XLOOKUP($B7,VALUE('STOCK ON HAND'!$E$1:$E$200),'STOCK ON HAND'!$H$1:$H$200,0)/D7} -> 0.83333333 | H7: =IF($F7=0,0,($G7*1/$F7)) -> 8.8383838 | I7: =SUMIFS('STOCK ON ORDER'!$L$2:$L$200,'STOCK ON ORDER'!$H$2:$H$200,VALUE($L7)) -> 1 | J7: =F7*10 -> 0.94285714 | K7: =IF(H7>10,0,IFERROR(MAX(0,J7-G7-I7),0)) -> 0 | L7: 10006909
A8: =IFERROR(VLOOKUP($B8,'AC and RGM only'!$K$2:$L$250,2,FALSE),"") -> DRINK RED BULL S/FREE 250ML | B8: 100404 | D8: 24 | E8: RED BULL S/FREE | F8: =AVERAGE(_xlfn.XLOOKUP($B8,'AC and RGM only'!$K$1:$K$150,'AC and RGM only'!$N$1:$T$150)) -> 0.017142857 | G8: {=_xlfn.XLOOKUP($B8,VALUE('STOCK ON HAND'!$E$1:$E$200),'STOCK ON HAND'!$H$1:$H$200,0)/D8} -> 0.33333333 | H8: =IF($F8=0,0,($G8*1/$F8)) -> 19.444444 | I8: =SUMIFS('STOCK ON ORDER'!$L$2:$L$200,'STOCK ON ORDER'!$H$2:$H$200,VALUE($L8)) -> 1 | J8: =F8*10 -> 0.17142857 | K8: =IF(H8>10,0,IFERROR(MAX(0,J8-G8-I8),0)) -> 0 | L8: 10006936
A9: =IFERROR(VLOOKUP($B9,'AC and RGM only'!$K$2:$L$250,2,FALSE),"") -> DRINK RED BULL TROPICAL 250ML | B9: 100405 | D9: 12 | E9: RED BULL TROPICAL | F9: =AVERAGE(_xlfn.XLOOKUP($B9,'AC and RGM only'!$K$1:$K$150,'AC and RGM only'!$N$1:$T$150)) -> 0.06 | G9: {=_xlfn.XLOOKUP($B9,VALUE('STOCK ON HAND'!$E$1:$E$200),'STOCK ON HAND'!$H$1:$H$200,0)/D9} -> 0.91666667 | H9: =IF($F9=0,0,($G9*1/$F9)) -> 15.277778 | I9: =SUMIFS('STOCK ON ORDER'!$L$2:$L$200,'STOCK ON ORDER'!$H$2:$H$200,VALUE($L9)) -> 0 | J9: =F9*10 -> 0.6 | K9: =IF(H9>10,0,IFERROR(MAX(0,J9-G9-I9),0)) -> 0 | L9: 10006942
A10: =IFERROR(VLOOKUP($B10,'AC and RGM only'!$K$2:$L$250,2,FALSE),"") -> DRINK JUICE POP TOP APPLE 250ML | B10: 100400 | D10: 24 | E10: POP TOP - APPLE | F10: =AVERAGE(_xlfn.XLOOKUP($B10,'AC and RGM only'!$K$1:$K$150,'AC and RGM only'!$N$1:$T$150)) -> 0.09 | G10: {=_xlfn.XLOOKUP($B10,VALUE('STOCK ON HAND'!$E$1:$E$200),'STOCK ON HAND'!$H$1:$H$200,0)/D10} -> 1 | H10: =IF($F10=0,0,($G10*1/$F10)) -> 11.111111 | I10: =SUMIFS('STOCK ON ORDER'!$L$2:$L$200,'STOCK ON ORDER'!$H$2:$H$200,VALUE($L10)) -> 0 | J10: =F10*10 -> 0.9 | K10: =IF(H10>10,0,IFERROR(MAX(0,J10-G10-I10),0)) -> 0 | L10: 10007182
A11: =IFERROR(VLOOKUP($B11,'AC and RGM only'!$K$2:$L$250,2,FALSE),"") -> DRINK JUICE POP TOP ORANGE 250ML | B11: 100401 | D11: 24 | E11: POP TOP - ORANGE | F11: =AVERAGE(_xlfn.XLOOKUP($B11,'AC and RGM only'!$K$1:$K$150,'AC and RGM only'!$N$1:$T$150)) -> 0.017142857 | G11: {=_xlfn.XLOOKUP($B11,VALUE('STOCK ON HAND'!$E$1:$E$200),'STOCK ON HAND'!$H$1:$H$200,0)/D11} -> 1.6666667 | H11: =IF($F11=0,0,($G11*1/$F11)) -> 97.222222 | I11: =SUMIFS('STOCK ON ORDER'!$L$2:$L$200,'STOCK ON ORDER'!$H$2:$H$200,VALUE($L11)) -> 0 | J11: =F11*10 -> 0.17142857 | K11: =IF(H11>10,0,IFERROR(MAX(0,J11-G11-I11),0)) -> 0 | L11: 10007184
A12: =IFERROR(VLOOKUP($B12,'AC and RGM only'!$K$2:$L$250,2,FALSE),"") -> DRINK JUICE APPLE SPRING VALLEY | B12: 100399 | D12: 12 | E12: SPRING VALLEY APPLE | F12: =AVERAGE(_xlfn.XLOOKUP($B12,'AC and RGM only'!$K$1:$K$150,'AC and RGM only'!$N$1:$T$150)) -> 0.032857143 | G12: {=_xlfn.XLOOKUP($B12,VALUE('STOCK ON HAND'!$E$1:$E$200),'STOCK ON HAND'!$H$1:$H$200,0)/D12} -> 1.5833333 | H12: =IF($F12=0,0,($G12*1/$F12)) -> 48.188406 | I12: =SUMIFS('STOCK ON ORDER'!$L$2:$L$200,'STOCK ON ORDER'!$H$2:$H$200,VALUE($L12)) -> 0 | J12: =F12*10 -> 0.32857143 | K12: =IF(H12>10,0,IFERROR(MAX(0,J12-G12-I12),0)) -> 0 | L12: 10008418
A13: =IFERROR(VLOOKUP($B13,'AC and RGM only'!$K$2:$L$250,2,FALSE),"") -> DRINK 7UP 600ML PET | B13: 16520 | D13: 24 | E13: 7UP BOTTLE | F13: =AVERAGE(_xlfn.XLOOKUP($B13,'AC and RGM only'!$K$1:$K$150,'AC and RGM only'!$N$1:$T$150)) -> 0.034285714 | G13: {=_xlfn.XLOOKUP($B13,VALUE('STOCK ON HAND'!$E$1:$E$200),'STOCK ON HAND'!$H$1:$H$200,0)/D13} -> 0.45833333 | H13: =IF($F13=0,0,($G13*1/$F13)) -> 13.368056 | I13: =SUMIFS('STOCK ON ORDER'!$L$2:$L$200,'STOCK ON ORDER'!$H$2:$H$200,VALUE($L13)) -> 0 | J13: =F13*10 -> 0.34285714 | K13: =IF(H13>10,0,IFERROR(MAX(0,J13-G13-I13),0)) -> 0 | L13: 3227
